<robot name = "robot">
    <link name="Segment0">
        <inertial>
            <origin xyz="0 0 1.8995257804483747" rpy="0 0 0"/>
            <mass value="1" />
            <inertia ixx="100" ixy="0" ixz="0" iyy="100" iyz="0" izz="100" />
        </inertial>
        <visual>
            <origin xyz="0 0 1.8995257804483747" rpy="0 0 0"/>
            <geometry>
                <box size="3 2 1" />
            </geometry>
            <material name="Green">
                <color rgba="0 1.0 0 1.0"/>
            </material>
        </visual>
        <collision>
            <origin xyz="0 0 1.8995257804483747" rpy="0 0 0"/>
            <geometry>
                <box size="3 2 1" />
            </geometry>
        </collision>
    </link>
    <joint name="Segment0_Segment1" type="revolute">
       <parent link="Segment0"/>
       <child  link="Segment1"/>
       <origin rpy="0 0 0" xyz="-1.5 1.0 1.1798659015732869" />
     <axis xyz="0 1 0"/>
       <limit effort="0.0" lower="-3.14159" upper="3.14159" velocity="0.0"/>
    </joint>
    <joint name="Segment0_Segment2" type="revolute">
       <parent link="Segment0"/>
       <child  link="Segment2"/>
       <origin rpy="0 0 0" xyz="-1.5 -1.0 1.0869869077600693" />
     <axis xyz="0 1 0"/>
       <limit effort="0.0" lower="-3.14159" upper="3.14159" velocity="0.0"/>
    </joint>
    <joint name="Segment0_Segment3" type="revolute">
       <parent link="Segment0"/>
       <child  link="Segment3"/>
       <origin rpy="0 0 0" xyz="1.5 -1.0 1.1854957357147329" />
     <axis xyz="0 1 0"/>
       <limit effort="0.0" lower="-3.14159" upper="3.14159" velocity="0.0"/>
    </joint>
    <joint name="Segment0_Segment4" type="revolute">
       <parent link="Segment0"/>
       <child  link="Segment4"/>
       <origin rpy="0 0 0" xyz="1.5 1.0 1.1575915984754377" />
     <axis xyz="0 1 0"/>
       <limit effort="0.0" lower="-3.14159" upper="3.14159" velocity="0.0"/>
    </joint>
    <link name="Segment1">
        <inertial>
            <origin xyz="0 0 0" rpy="0 0 0"/>
            <mass value="1" />
            <inertia ixx="100" ixy="0" ixz="0" iyy="100" iyz="0" izz="100" />
        </inertial>
        <visual>
            <origin xyz="0 0 0" rpy="0 0 0"/>
            <geometry>
                <box size="0.5101395997677282 0.5219979885906089 0.43931975775017573" />
            </geometry>
            <material name="Blue">
                <color rgba="0 0 1.0 1.0"/>
            </material>
        </visual>
        <collision>
            <origin xyz="0 0 0" rpy="0 0 0"/>
            <geometry>
                <box size="0.5101395997677282 0.5219979885906089 0.43931975775017573" />
            </geometry>
        </collision>
    </link>
    <joint name="Segment1_Segment5" type="revolute">
       <parent link="Segment1"/>
       <child  link="Segment5"/>
       <origin rpy="0 0 0" xyz="0.0 0.0 -0.475900374827012" />
     <axis xyz="0 1 0"/>
       <limit effort="0.0" lower="-3.14159" upper="3.14159" velocity="0.0"/>
    </joint>
    <link name="Segment2">
        <inertial>
            <origin xyz="0 0 0" rpy="0 0 0"/>
            <mass value="1" />
            <inertia ixx="100" ixy="0" ixz="0" iyy="100" iyz="0" izz="100" />
        </inertial>
        <visual>
            <origin xyz="0 0 0" rpy="0 0 0"/>
            <geometry>
                <box size="0.6065921839091469 0.5360898311200991 0.6250777453766106" />
            </geometry>
            <material name="Blue">
                <color rgba="0 0 1.0 1.0"/>
            </material>
        </visual>
        <collision>
            <origin xyz="0 0 0" rpy="0 0 0"/>
            <geometry>
                <box size="0.6065921839091469 0.5360898311200991 0.6250777453766106" />
            </geometry>
        </collision>
    </link>
    <joint name="Segment2_Segment6" type="revolute">
       <parent link="Segment2"/>
       <child  link="Segment6"/>
       <origin rpy="0 0 0" xyz="0.0 -0.0 -0.6608423431610126" />
     <axis xyz="0 1 0"/>
       <limit effort="0.0" lower="-3.14159" upper="3.14159" velocity="0.0"/>
    </joint>
    <link name="Segment3">
        <inertial>
            <origin xyz="0 0 0" rpy="0 0 0"/>
            <mass value="1" />
            <inertia ixx="100" ixy="0" ixz="0" iyy="100" iyz="0" izz="100" />
        </inertial>
        <visual>
            <origin xyz="0 0 0" rpy="0 0 0"/>
            <geometry>
                <box size="0.4081112638172561 0.5160779340937226 0.4280600894672837" />
            </geometry>
            <material name="Blue">
                <color rgba="0 0 1.0 1.0"/>
            </material>
        </visual>
        <collision>
            <origin xyz="0 0 0" rpy="0 0 0"/>
            <geometry>
                <box size="0.4081112638172561 0.5160779340937226 0.4280600894672837" />
            </geometry>
        </collision>
    </link>
    <joint name="Segment3_Segment7" type="revolute">
       <parent link="Segment3"/>
       <child  link="Segment7"/>
       <origin rpy="0 0 0" xyz="0.0 0.0 -0.5103607981980289" />
     <axis xyz="0 1 0"/>
       <limit effort="0.0" lower="-3.14159" upper="3.14159" velocity="0.0"/>
    </joint>
    <link name="Segment4">
        <inertial>
            <origin xyz="0 0 0" rpy="0 0 0"/>
            <mass value="1" />
            <inertia ixx="100" ixy="0" ixz="0" iyy="100" iyz="0" izz="100" />
        </inertial>
        <visual>
            <origin xyz="0 0 0" rpy="0 0 0"/>
            <geometry>
                <box size="0.512856500658252 0.4113843560917975 0.4838683639458742" />
            </geometry>
            <material name="Green">
                <color rgba="0 1.0 0 1.0"/>
            </material>
        </visual>
        <collision>
            <origin xyz="0 0 0" rpy="0 0 0"/>
            <geometry>
                <box size="0.512856500658252 0.4113843560917975 0.4838683639458742" />
            </geometry>
        </collision>
    </link>
    <joint name="Segment4_Segment8" type="revolute">
       <parent link="Segment4"/>
       <child  link="Segment8"/>
       <origin rpy="0 0 0" xyz="0.0 -0.0 -0.7021851544865088" />
     <axis xyz="0 1 0"/>
       <limit effort="0.0" lower="-3.14159" upper="3.14159" velocity="0.0"/>
    </joint>
    <link name="Segment5">
        <inertial>
            <origin xyz="0 0 0" rpy="0 0 0"/>
            <mass value="1" />
            <inertia ixx="100" ixy="0" ixz="0" iyy="100" iyz="0" izz="100" />
        </inertial>
        <visual>
            <origin xyz="0 0 0" rpy="0 0 0"/>
            <geometry>
                <box size="0.7089704815524642 0.4696796402348605 0.5124809919038482" />
            </geometry>
            <material name="Green">
                <color rgba="0 1.0 0 1.0"/>
            </material>
        </visual>
        <collision>
            <origin xyz="0 0 0" rpy="0 0 0"/>
            <geometry>
                <box size="0.7089704815524642 0.4696796402348605 0.5124809919038482" />
            </geometry>
        </collision>
    </link>
    <link name="Segment6">
        <inertial>
            <origin xyz="0 0 0" rpy="0 0 0"/>
            <mass value="1" />
            <inertia ixx="100" ixy="0" ixz="0" iyy="100" iyz="0" izz="100" />
        </inertial>
        <visual>
            <origin xyz="0 0 0" rpy="0 0 0"/>
            <geometry>
                <box size="0.5851824177486759 0.6834961157738008 0.6966069409454145" />
            </geometry>
            <material name="Blue">
                <color rgba="0 0 1.0 1.0"/>
            </material>
        </visual>
        <collision>
            <origin xyz="0 0 0" rpy="0 0 0"/>
            <geometry>
                <box size="0.5851824177486759 0.6834961157738008 0.6966069409454145" />
            </geometry>
        </collision>
    </link>
    <link name="Segment7">
        <inertial>
            <origin xyz="0 0 0" rpy="0 0 0"/>
            <mass value="1" />
            <inertia ixx="100" ixy="0" ixz="0" iyy="100" iyz="0" izz="100" />
        </inertial>
        <visual>
            <origin xyz="0 0 0" rpy="0 0 0"/>
            <geometry>
                <box size="0.5489079268069201 0.6981846072605138 0.5926615069287743" />
            </geometry>
            <material name="Green">
                <color rgba="0 1.0 0 1.0"/>
            </material>
        </visual>
        <collision>
            <origin xyz="0 0 0" rpy="0 0 0"/>
            <geometry>
                <box size="0.5489079268069201 0.6981846072605138 0.5926615069287743" />
            </geometry>
        </collision>
    </link>
    <link name="Segment8">
        <inertial>
            <origin xyz="0 0 0" rpy="0 0 0"/>
            <mass value="1" />
            <inertia ixx="100" ixy="0" ixz="0" iyy="100" iyz="0" izz="100" />
        </inertial>
        <visual>
            <origin xyz="0 0 0" rpy="0 0 0"/>
            <geometry>
                <box size="0.40551443654699965 0.8975174300903845 0.9205019450271434" />
            </geometry>
            <material name="Blue">
                <color rgba="0 0 1.0 1.0"/>
            </material>
        </visual>
        <collision>
            <origin xyz="0 0 0" rpy="0 0 0"/>
            <geometry>
                <box size="0.40551443654699965 0.8975174300903845 0.9205019450271434" />
            </geometry>
        </collision>
    </link>
</robot>