<robot name = "robot">
    <link name="Torso">
        <inertial>
            <origin xyz="0.6557584097952207 0.5598988280414737 0.9303725266913208" rpy="0 0 0"/>
            <mass value="1" />
            <inertia ixx="100" ixy="0" ixz="0" iyy="100" iyz="0" izz="100" />
        </inertial>
        <visual>
            <origin xyz="0.6557584097952207 0.5598988280414737 0.9303725266913208" rpy="0 0 0"/>
            <geometry>
                <box size="1.3115168195904414 1.1197976560829475 1.8607450533826415" />
            </geometry>
            <material name="Blue">
                <color rgba="0 0 1.0 1.0"/>
            </material>
        </visual>
        <collision>
            <origin xyz="0.6557584097952207 0.5598988280414737 0.9303725266913208" rpy="0 0 0"/>
            <geometry>
                <box size="1.3115168195904414 1.1197976560829475 1.8607450533826415" />
            </geometry>
        </collision>
    </link>
    <joint name="Torso_BackLeg1" type="revolute">
       <parent link="Torso"/>
       <child  link="BackLeg1"/>
       <origin rpy="0 0 0" xyz="-0.6557584097952207 0.5598988280414737 0" />
     <axis xyz="0 0 1"/>
       <limit effort="0.0" lower="-3.14159" upper="3.14159" velocity="0.0"/>
    </joint>
    <link name="BackLeg1">
        <inertial>
            <origin xyz="0.6557584097952207 0.5598988280414737 0.9303725266913208" rpy="0 0 0"/>
            <mass value="1" />
            <inertia ixx="100" ixy="0" ixz="0" iyy="100" iyz="0" izz="100" />
        </inertial>
        <visual>
            <origin xyz="0.6557584097952207 0.5598988280414737 0.9303725266913208" rpy="0 0 0"/>
            <geometry>
                <box size="1.3115168195904414 1.1197976560829475 1.8607450533826415" />
            </geometry>
            <material name="Green">
                <color rgba="0 1.0 0 1.0"/>
            </material>
        </visual>
        <collision>
            <origin xyz="0.6557584097952207 0.5598988280414737 0.9303725266913208" rpy="0 0 0"/>
            <geometry>
                <box size="1.3115168195904414 1.1197976560829475 1.8607450533826415" />
            </geometry>
        </collision>
    </link>
    <joint name="Torso_FrontLeg1" type="revolute">
       <parent link="Torso"/>
       <child  link="FrontLeg1"/>
       <origin rpy="0 0 0" xyz="0.6557584097952207 0.5598988280414737 0" />
     <axis xyz="0 0 1"/>
       <limit effort="0.0" lower="-3.14159" upper="3.14159" velocity="0.0"/>
    </joint>
    <link name="FrontLeg1">
        <inertial>
            <origin xyz="0.6557584097952207 0.5598988280414737 0.9303725266913208" rpy="0 0 0"/>
            <mass value="1" />
            <inertia ixx="100" ixy="0" ixz="0" iyy="100" iyz="0" izz="100" />
        </inertial>
        <visual>
            <origin xyz="0.6557584097952207 0.5598988280414737 0.9303725266913208" rpy="0 0 0"/>
            <geometry>
                <box size="1.3115168195904414 1.1197976560829475 1.8607450533826415" />
            </geometry>
            <material name="Green">
                <color rgba="0 1.0 0 1.0"/>
            </material>
        </visual>
        <collision>
            <origin xyz="0.6557584097952207 0.5598988280414737 0.9303725266913208" rpy="0 0 0"/>
            <geometry>
                <box size="1.3115168195904414 1.1197976560829475 1.8607450533826415" />
            </geometry>
        </collision>
    </link>
    <link name="FrontLeg2">
        <inertial>
            <origin xyz="1.4943756205072196 0.5328178399680756 1.2992435653244767" rpy="0 0 0"/>
            <mass value="1" />
            <inertia ixx="100" ixy="0" ixz="0" iyy="100" iyz="0" izz="100" />
        </inertial>
        <visual>
            <origin xyz="1.4943756205072196 0.5328178399680756 1.2992435653244767" rpy="0 0 0"/>
            <geometry>
                <box size="2.9887512410144392 1.0656356799361513 2.5984871306489534" />
            </geometry>
            <material name="Blue">
                <color rgba="0 0 1.0 1.0"/>
            </material>
        </visual>
        <collision>
            <origin xyz="1.4943756205072196 0.5328178399680756 1.2992435653244767" rpy="0 0 0"/>
            <geometry>
                <box size="2.9887512410144392 1.0656356799361513 2.5984871306489534" />
            </geometry>
        </collision>
    </link>
    <joint name="FrontLeg1_FrontLeg2" type="revolute">
       <parent link="FrontLeg1"/>
       <child  link="FrontLeg2"/>
       <origin rpy="0 0 0" xyz="1.4943756205072196 0.5328178399680756 0" />
     <axis xyz="0 0 1"/>
       <limit effort="0.0" lower="-3.14159" upper="3.14159" velocity="0.0"/>
    </joint>
    <link name="FrontLeg3">
        <inertial>
            <origin xyz="1.1725320894365492 0.9844478308419815 1.3771855594338334" rpy="0 0 0"/>
            <mass value="1" />
            <inertia ixx="100" ixy="0" ixz="0" iyy="100" iyz="0" izz="100" />
        </inertial>
        <visual>
            <origin xyz="1.1725320894365492 0.9844478308419815 1.3771855594338334" rpy="0 0 0"/>
            <geometry>
                <box size="2.3450641788730984 1.968895661683963 2.7543711188676667" />
            </geometry>
            <material name="Green">
                <color rgba="0 1.0 0 1.0"/>
            </material>
        </visual>
        <collision>
            <origin xyz="1.1725320894365492 0.9844478308419815 1.3771855594338334" rpy="0 0 0"/>
            <geometry>
                <box size="2.3450641788730984 1.968895661683963 2.7543711188676667" />
            </geometry>
        </collision>
    </link>
    <joint name="FrontLeg2_FrontLeg3" type="revolute">
       <parent link="FrontLeg2"/>
       <child  link="FrontLeg3"/>
       <origin rpy="0 0 0" xyz="1.1725320894365492 1.1725320894365492 0" />
     <axis xyz="0 0 1"/>
       <limit effort="0.0" lower="-3.14159" upper="3.14159" velocity="0.0"/>
    </joint>
    <link name="FrontLeg4">
        <inertial>
            <origin xyz="1.4813088728445796 0.6789823448405308 1.084133977988465" rpy="0 0 0"/>
            <mass value="1" />
            <inertia ixx="100" ixy="0" ixz="0" iyy="100" iyz="0" izz="100" />
        </inertial>
        <visual>
            <origin xyz="1.4813088728445796 0.6789823448405308 1.084133977988465" rpy="0 0 0"/>
            <geometry>
                <box size="2.962617745689159 1.3579646896810615 2.16826795597693" />
            </geometry>
            <material name="Blue">
                <color rgba="0 0 1.0 1.0"/>
            </material>
        </visual>
        <collision>
            <origin xyz="1.4813088728445796 0.6789823448405308 1.084133977988465" rpy="0 0 0"/>
            <geometry>
                <box size="2.962617745689159 1.3579646896810615 2.16826795597693" />
            </geometry>
        </collision>
    </link>
    <joint name="FrontLeg3_FrontLeg4" type="revolute">
       <parent link="FrontLeg3"/>
       <child  link="FrontLeg4"/>
       <origin rpy="0 0 0" xyz="1.4813088728445796 0.6789823448405308 0" />
     <axis xyz="0 0 1"/>
       <limit effort="0.0" lower="-3.14159" upper="3.14159" velocity="0.0"/>
    </joint>
    <link name="FrontLeg5">
        <inertial>
            <origin xyz="0.8327169607896239 0.8021053615419 0.7917189179702047" rpy="0 0 0"/>
            <mass value="1" />
            <inertia ixx="100" ixy="0" ixz="0" iyy="100" iyz="0" izz="100" />
        </inertial>
        <visual>
            <origin xyz="0.8327169607896239 0.8021053615419 0.7917189179702047" rpy="0 0 0"/>
            <geometry>
                <box size="1.6654339215792477 1.6042107230838 1.5834378359404093" />
            </geometry>
            <material name="Green">
                <color rgba="0 1.0 0 1.0"/>
            </material>
        </visual>
        <collision>
            <origin xyz="0.8327169607896239 0.8021053615419 0.7917189179702047" rpy="0 0 0"/>
            <geometry>
                <box size="1.6654339215792477 1.6042107230838 1.5834378359404093" />
            </geometry>
        </collision>
    </link>
    <joint name="FrontLeg4_FrontLeg5" type="revolute">
       <parent link="FrontLeg4"/>
       <child  link="FrontLeg5"/>
       <origin rpy="0 0 0" xyz="0.8327169607896239 0.8327169607896239 0" />
     <axis xyz="0 0 1"/>
       <limit effort="0.0" lower="-3.14159" upper="3.14159" velocity="0.0"/>
    </joint>
    <link name="FrontLeg6">
        <inertial>
            <origin xyz="0.8973492663699265 0.887498323837534 0.5978782635303344" rpy="0 0 0"/>
            <mass value="1" />
            <inertia ixx="100" ixy="0" ixz="0" iyy="100" iyz="0" izz="100" />
        </inertial>
        <visual>
            <origin xyz="0.8973492663699265 0.887498323837534 0.5978782635303344" rpy="0 0 0"/>
            <geometry>
                <box size="1.794698532739853 1.774996647675068 1.1957565270606687" />
            </geometry>
            <material name="Green">
                <color rgba="0 1.0 0 1.0"/>
            </material>
        </visual>
        <collision>
            <origin xyz="0.8973492663699265 0.887498323837534 0.5978782635303344" rpy="0 0 0"/>
            <geometry>
                <box size="1.794698532739853 1.774996647675068 1.1957565270606687" />
            </geometry>
        </collision>
    </link>
    <joint name="FrontLeg5_FrontLeg6" type="revolute">
       <parent link="FrontLeg5"/>
       <child  link="FrontLeg6"/>
       <origin rpy="0 0 0" xyz="0.8973492663699265 0.8973492663699265 0" />
     <axis xyz="0 0 1"/>
       <limit effort="0.0" lower="-3.14159" upper="3.14159" velocity="0.0"/>
    </joint>
    <link name="FrontLeg7">
        <inertial>
            <origin xyz="0.9095082690977991 0.7681160107749606 0.6523463806187622" rpy="0 0 0"/>
            <mass value="1" />
            <inertia ixx="100" ixy="0" ixz="0" iyy="100" iyz="0" izz="100" />
        </inertial>
        <visual>
            <origin xyz="0.9095082690977991 0.7681160107749606 0.6523463806187622" rpy="0 0 0"/>
            <geometry>
                <box size="1.8190165381955983 1.5362320215499212 1.3046927612375243" />
            </geometry>
            <material name="Green">
                <color rgba="0 1.0 0 1.0"/>
            </material>
        </visual>
        <collision>
            <origin xyz="0.9095082690977991 0.7681160107749606 0.6523463806187622" rpy="0 0 0"/>
            <geometry>
                <box size="1.8190165381955983 1.5362320215499212 1.3046927612375243" />
            </geometry>
        </collision>
    </link>
    <joint name="FrontLeg6_FrontLeg7" type="revolute">
       <parent link="FrontLeg6"/>
       <child  link="FrontLeg7"/>
       <origin rpy="0 0 0" xyz="0.9095082690977991 0.9095082690977991 0" />
     <axis xyz="0 0 1"/>
       <limit effort="0.0" lower="-3.14159" upper="3.14159" velocity="0.0"/>
    </joint>
    <link name="FrontLeg8">
        <inertial>
            <origin xyz="0.6423720107686572 0.5800729807711108 1.2513639117298498" rpy="0 0 0"/>
            <mass value="1" />
            <inertia ixx="100" ixy="0" ixz="0" iyy="100" iyz="0" izz="100" />
        </inertial>
        <visual>
            <origin xyz="0.6423720107686572 0.5800729807711108 1.2513639117298498" rpy="0 0 0"/>
            <geometry>
                <box size="1.2847440215373145 1.1601459615422216 2.5027278234596997" />
            </geometry>
            <material name="Green">
                <color rgba="0 1.0 0 1.0"/>
            </material>
        </visual>
        <collision>
            <origin xyz="0.6423720107686572 0.5800729807711108 1.2513639117298498" rpy="0 0 0"/>
            <geometry>
                <box size="1.2847440215373145 1.1601459615422216 2.5027278234596997" />
            </geometry>
        </collision>
    </link>
    <joint name="FrontLeg7_FrontLeg8" type="revolute">
       <parent link="FrontLeg7"/>
       <child  link="FrontLeg8"/>
       <origin rpy="0 0 0" xyz="0.6423720107686572 0.6423720107686572 0" />
     <axis xyz="0 0 1"/>
       <limit effort="0.0" lower="-3.14159" upper="3.14159" velocity="0.0"/>
    </joint>
    <link name="FrontLeg9">
        <inertial>
            <origin xyz="0.6677056014948568 0.5490184104491916 0.7821036311425013" rpy="0 0 0"/>
            <mass value="1" />
            <inertia ixx="100" ixy="0" ixz="0" iyy="100" iyz="0" izz="100" />
        </inertial>
        <visual>
            <origin xyz="0.6677056014948568 0.5490184104491916 0.7821036311425013" rpy="0 0 0"/>
            <geometry>
                <box size="1.3354112029897136 1.0980368208983833 1.5642072622850025" />
            </geometry>
            <material name="Blue">
                <color rgba="0 0 1.0 1.0"/>
            </material>
        </visual>
        <collision>
            <origin xyz="0.6677056014948568 0.5490184104491916 0.7821036311425013" rpy="0 0 0"/>
            <geometry>
                <box size="1.3354112029897136 1.0980368208983833 1.5642072622850025" />
            </geometry>
        </collision>
    </link>
    <joint name="FrontLeg8_FrontLeg9" type="revolute">
       <parent link="FrontLeg8"/>
       <child  link="FrontLeg9"/>
       <origin rpy="0 0 0" xyz="0.6677056014948568 0.5490184104491916 0" />
     <axis xyz="0 0 1"/>
       <limit effort="0.0" lower="-3.14159" upper="3.14159" velocity="0.0"/>
    </joint>
</robot>