<robot name = "robot">
    <link name="Segment0">
        <inertial>
            <origin xyz="0 0 2.707228319086552" rpy="0 0 0"/>
            <mass value="1" />
            <inertia ixx="100" ixy="0" ixz="0" iyy="100" iyz="0" izz="100" />
        </inertial>
        <visual>
            <origin xyz="0 0 2.707228319086552" rpy="0 0 0"/>
            <geometry>
                <box size="3 2 1" />
            </geometry>
            <material name="Green">
                <color rgba="0 1.0 0 1.0"/>
            </material>
        </visual>
        <collision>
            <origin xyz="0 0 2.707228319086552" rpy="0 0 0"/>
            <geometry>
                <box size="3 2 1" />
            </geometry>
        </collision>
    </link>
    <joint name="Segment0_Segment1" type="revolute">
       <parent link="Segment0"/>
       <child  link="Segment1"/>
       <origin rpy="0 0 0" xyz="-1.5 1.0 1.9627215488076275" />
     <axis xyz="0 1 0"/>
       <limit effort="0.0" lower="-3.14159" upper="3.14159" velocity="0.0"/>
    </joint>
    <joint name="Segment0_Segment2" type="revolute">
       <parent link="Segment0"/>
       <child  link="Segment2"/>
       <origin rpy="0 0 0" xyz="-1.5 -1.0 1.7715920844779132" />
     <axis xyz="0 1 0"/>
       <limit effort="0.0" lower="-3.14159" upper="3.14159" velocity="0.0"/>
    </joint>
    <joint name="Segment0_Segment3" type="revolute">
       <parent link="Segment0"/>
       <child  link="Segment3"/>
       <origin rpy="0 0 0" xyz="1.5 -1.0 1.9168887591533632" />
     <axis xyz="0 1 0"/>
       <limit effort="0.0" lower="-3.14159" upper="3.14159" velocity="0.0"/>
    </joint>
    <joint name="Segment0_Segment4" type="revolute">
       <parent link="Segment0"/>
       <child  link="Segment4"/>
       <origin rpy="0 0 0" xyz="1.5 1.0 1.84957403933136" />
     <axis xyz="0 1 0"/>
       <limit effort="0.0" lower="-3.14159" upper="3.14159" velocity="0.0"/>
    </joint>
    <link name="Segment1">
        <inertial>
            <origin xyz="0 0 0" rpy="0 0 0"/>
            <mass value="1" />
            <inertia ixx="100" ixy="0" ixz="0" iyy="100" iyz="0" izz="100" />
        </inertial>
        <visual>
            <origin xyz="0 0 0" rpy="0 0 0"/>
            <geometry>
                <box size="0.5734697829276786 1.0281587894145017 0.48901354055784924" />
            </geometry>
            <material name="Blue">
                <color rgba="0 0 1.0 1.0"/>
            </material>
        </visual>
        <collision>
            <origin xyz="0 0 0" rpy="0 0 0"/>
            <geometry>
                <box size="0.5734697829276786 1.0281587894145017 0.48901354055784924" />
            </geometry>
        </collision>
    </link>
    <joint name="Segment1_Segment5" type="revolute">
       <parent link="Segment1"/>
       <child  link="Segment5"/>
       <origin rpy="0 0 0" xyz="0.0 0.0 -0.5402201170439216" />
     <axis xyz="0 1 0"/>
       <limit effort="0.0" lower="-3.14159" upper="3.14159" velocity="0.0"/>
    </joint>
    <link name="Segment2">
        <inertial>
            <origin xyz="0 0 0" rpy="0 0 0"/>
            <mass value="1" />
            <inertia ixx="100" ixy="0" ixz="0" iyy="100" iyz="0" izz="100" />
        </inertial>
        <visual>
            <origin xyz="0 0 0" rpy="0 0 0"/>
            <geometry>
                <box size="0.5252632154205142 0.4177342690657742 0.8712724692172776" />
            </geometry>
            <material name="Blue">
                <color rgba="0 0 1.0 1.0"/>
            </material>
        </visual>
        <collision>
            <origin xyz="0 0 0" rpy="0 0 0"/>
            <geometry>
                <box size="0.5252632154205142 0.4177342690657742 0.8712724692172776" />
            </geometry>
        </collision>
    </link>
    <joint name="Segment2_Segment6" type="revolute">
       <parent link="Segment2"/>
       <child  link="Segment6"/>
       <origin rpy="0 0 0" xyz="0.0 -0.0 -0.7472119991198538" />
     <axis xyz="0 1 0"/>
       <limit effort="0.0" lower="-3.14159" upper="3.14159" velocity="0.0"/>
    </joint>
    <link name="Segment3">
        <inertial>
            <origin xyz="0 0 0" rpy="0 0 0"/>
            <mass value="1" />
            <inertia ixx="100" ixy="0" ixz="0" iyy="100" iyz="0" izz="100" />
        </inertial>
        <visual>
            <origin xyz="0 0 0" rpy="0 0 0"/>
            <geometry>
                <box size="0.8840333928890552 0.6927879425388886 0.5806791198663775" />
            </geometry>
            <material name="Blue">
                <color rgba="0 0 1.0 1.0"/>
            </material>
        </visual>
        <collision>
            <origin xyz="0 0 0" rpy="0 0 0"/>
            <geometry>
                <box size="0.8840333928890552 0.6927879425388886 0.5806791198663775" />
            </geometry>
        </collision>
    </link>
    <joint name="Segment3_Segment7" type="revolute">
       <parent link="Segment3"/>
       <child  link="Segment7"/>
       <origin rpy="0 0 0" xyz="0.0 0.0 -0.6548580372632737" />
     <axis xyz="0 1 0"/>
       <limit effort="0.0" lower="-3.14159" upper="3.14159" velocity="0.0"/>
    </joint>
    <link name="Segment4">
        <inertial>
            <origin xyz="0 0 0" rpy="0 0 0"/>
            <mass value="1" />
            <inertia ixx="100" ixy="0" ixz="0" iyy="100" iyz="0" izz="100" />
        </inertial>
        <visual>
            <origin xyz="0 0 0" rpy="0 0 0"/>
            <geometry>
                <box size="0.5241985433134593 0.6558395492022813 0.7153085595103843" />
            </geometry>
            <material name="Green">
                <color rgba="0 1.0 0 1.0"/>
            </material>
        </visual>
        <collision>
            <origin xyz="0 0 0" rpy="0 0 0"/>
            <geometry>
                <box size="0.5241985433134593 0.6558395492022813 0.7153085595103843" />
            </geometry>
        </collision>
    </link>
    <joint name="Segment4_Segment8" type="revolute">
       <parent link="Segment4"/>
       <child  link="Segment8"/>
       <origin rpy="0 0 0" xyz="0.0 -0.0 -0.5677665678881216" />
     <axis xyz="0 1 0"/>
       <limit effort="0.0" lower="-3.14159" upper="3.14159" velocity="0.0"/>
    </joint>
    <link name="Segment5">
        <inertial>
            <origin xyz="0 0 0" rpy="0 0 0"/>
            <mass value="1" />
            <inertia ixx="100" ixy="0" ixz="0" iyy="100" iyz="0" izz="100" />
        </inertial>
        <visual>
            <origin xyz="0 0 0" rpy="0 0 0"/>
            <geometry>
                <box size="0.7139961229005476 0.512294394721303 0.5914266935299939" />
            </geometry>
            <material name="Blue">
                <color rgba="0 0 1.0 1.0"/>
            </material>
        </visual>
        <collision>
            <origin xyz="0 0 0" rpy="0 0 0"/>
            <geometry>
                <box size="0.7139961229005476 0.512294394721303 0.5914266935299939" />
            </geometry>
        </collision>
    </link>
    <joint name="Segment5_Segment9" type="revolute">
       <parent link="Segment5"/>
       <child  link="Segment9"/>
       <origin rpy="0 0 0" xyz="0.0 0.0 -0.5269691919108676" />
     <axis xyz="0 1 0"/>
       <limit effort="0.0" lower="-3.14159" upper="3.14159" velocity="0.0"/>
    </joint>
    <link name="Segment6">
        <inertial>
            <origin xyz="0 0 0" rpy="0 0 0"/>
            <mass value="1" />
            <inertia ixx="100" ixy="0" ixz="0" iyy="100" iyz="0" izz="100" />
        </inertial>
        <visual>
            <origin xyz="0 0 0" rpy="0 0 0"/>
            <geometry>
                <box size="0.7105311111327632 0.6153594288393115 0.6231515290224299" />
            </geometry>
            <material name="Blue">
                <color rgba="0 0 1.0 1.0"/>
            </material>
        </visual>
        <collision>
            <origin xyz="0 0 0" rpy="0 0 0"/>
            <geometry>
                <box size="0.7105311111327632 0.6153594288393115 0.6231515290224299" />
            </geometry>
        </collision>
    </link>
    <joint name="Segment6_Segment10" type="revolute">
       <parent link="Segment6"/>
       <child  link="Segment10"/>
       <origin rpy="0 0 0" xyz="0.0 -0.0 -0.5592484409957306" />
     <axis xyz="0 1 0"/>
       <limit effort="0.0" lower="-3.14159" upper="3.14159" velocity="0.0"/>
    </joint>
    <link name="Segment7">
        <inertial>
            <origin xyz="0 0 0" rpy="0 0 0"/>
            <mass value="1" />
            <inertia ixx="100" ixy="0" ixz="0" iyy="100" iyz="0" izz="100" />
        </inertial>
        <visual>
            <origin xyz="0 0 0" rpy="0 0 0"/>
            <geometry>
                <box size="0.498547312337992 0.6763834231684193 0.7290369546601698" />
            </geometry>
            <material name="Green">
                <color rgba="0 1.0 0 1.0"/>
            </material>
        </visual>
        <collision>
            <origin xyz="0 0 0" rpy="0 0 0"/>
            <geometry>
                <box size="0.498547312337992 0.6763834231684193 0.7290369546601698" />
            </geometry>
        </collision>
    </link>
    <joint name="Segment7_Segment11" type="revolute">
       <parent link="Segment7"/>
       <child  link="Segment11"/>
       <origin rpy="0 0 0" xyz="0.0 0.0 -0.6608565045569106" />
     <axis xyz="0 1 0"/>
       <limit effort="0.0" lower="-3.14159" upper="3.14159" velocity="0.0"/>
    </joint>
    <link name="Segment8">
        <inertial>
            <origin xyz="0 0 0" rpy="0 0 0"/>
            <mass value="1" />
            <inertia ixx="100" ixy="0" ixz="0" iyy="100" iyz="0" izz="100" />
        </inertial>
        <visual>
            <origin xyz="0 0 0" rpy="0 0 0"/>
            <geometry>
                <box size="0.4387677412156027 0.4377197855879079 0.4202245762658591" />
            </geometry>
            <material name="Blue">
                <color rgba="0 0 1.0 1.0"/>
            </material>
        </visual>
        <collision>
            <origin xyz="0 0 0" rpy="0 0 0"/>
            <geometry>
                <box size="0.4387677412156027 0.4377197855879079 0.4202245762658591" />
            </geometry>
        </collision>
    </link>
    <joint name="Segment8_Segment12" type="revolute">
       <parent link="Segment8"/>
       <child  link="Segment12"/>
       <origin rpy="0 0 0" xyz="0.0 -0.0 -0.4856314965903752" />
     <axis xyz="0 1 0"/>
       <limit effort="0.0" lower="-3.14159" upper="3.14159" velocity="0.0"/>
    </joint>
    <link name="Segment9">
        <inertial>
            <origin xyz="0 0 0" rpy="0 0 0"/>
            <mass value="1" />
            <inertia ixx="100" ixy="0" ixz="0" iyy="100" iyz="0" izz="100" />
        </inertial>
        <visual>
            <origin xyz="0 0 0" rpy="0 0 0"/>
            <geometry>
                <box size="0.4929594201236499 0.8473972803022634 0.4625116902917413" />
            </geometry>
            <material name="Blue">
                <color rgba="0 0 1.0 1.0"/>
            </material>
        </visual>
        <collision>
            <origin xyz="0 0 0" rpy="0 0 0"/>
            <geometry>
                <box size="0.4929594201236499 0.8473972803022634 0.4625116902917413" />
            </geometry>
        </collision>
    </link>
    <link name="Segment10">
        <inertial>
            <origin xyz="0 0 0" rpy="0 0 0"/>
            <mass value="1" />
            <inertia ixx="100" ixy="0" ixz="0" iyy="100" iyz="0" izz="100" />
        </inertial>
        <visual>
            <origin xyz="0 0 0" rpy="0 0 0"/>
            <geometry>
                <box size="0.7150228021600109 0.6470715567998385 0.49534535296903137" />
            </geometry>
            <material name="Blue">
                <color rgba="0 0 1.0 1.0"/>
            </material>
        </visual>
        <collision>
            <origin xyz="0 0 0" rpy="0 0 0"/>
            <geometry>
                <box size="0.7150228021600109 0.6470715567998385 0.49534535296903137" />
            </geometry>
        </collision>
    </link>
    <link name="Segment11">
        <inertial>
            <origin xyz="0 0 0" rpy="0 0 0"/>
            <mass value="1" />
            <inertia ixx="100" ixy="0" ixz="0" iyy="100" iyz="0" izz="100" />
        </inertial>
        <visual>
            <origin xyz="0 0 0" rpy="0 0 0"/>
            <geometry>
                <box size="0.42629996009445575 0.9541307465317413 0.5926760544536515" />
            </geometry>
            <material name="Green">
                <color rgba="0 1.0 0 1.0"/>
            </material>
        </visual>
        <collision>
            <origin xyz="0 0 0" rpy="0 0 0"/>
            <geometry>
                <box size="0.42629996009445575 0.9541307465317413 0.5926760544536515" />
            </geometry>
        </collision>
    </link>
    <link name="Segment12">
        <inertial>
            <origin xyz="0 0 0" rpy="0 0 0"/>
            <mass value="1" />
            <inertia ixx="100" ixy="0" ixz="0" iyy="100" iyz="0" izz="100" />
        </inertial>
        <visual>
            <origin xyz="0 0 0" rpy="0 0 0"/>
            <geometry>
                <box size="0.6173289378556656 0.6838774609472856 0.5510384169148913" />
            </geometry>
            <material name="Blue">
                <color rgba="0 0 1.0 1.0"/>
            </material>
        </visual>
        <collision>
            <origin xyz="0 0 0" rpy="0 0 0"/>
            <geometry>
                <box size="0.6173289378556656 0.6838774609472856 0.5510384169148913" />
            </geometry>
        </collision>
    </link>
</robot>