<robot name = "robot">
    <link name="Segment0">
        <inertial>
            <origin xyz="0 0 2.3813402665475327" rpy="0 0 0"/>
            <mass value="1" />
            <inertia ixx="100" ixy="0" ixz="0" iyy="100" iyz="0" izz="100" />
        </inertial>
        <visual>
            <origin xyz="0 0 2.3813402665475327" rpy="0 0 0"/>
            <geometry>
                <box size="3 2 1" />
            </geometry>
            <material name="Green">
                <color rgba="0 1.0 0 1.0"/>
            </material>
        </visual>
        <collision>
            <origin xyz="0 0 2.3813402665475327" rpy="0 0 0"/>
            <geometry>
                <box size="3 2 1" />
            </geometry>
        </collision>
    </link>
    <joint name="Segment0_Segment1" type="revolute">
       <parent link="Segment0"/>
       <child  link="Segment1"/>
       <origin rpy="0 0 0" xyz="-1.5 1.0 1.4116544548481307" />
     <axis xyz="0 1 0"/>
       <limit effort="0.0" lower="-3.14159" upper="3.14159" velocity="0.0"/>
    </joint>
    <joint name="Segment0_Segment2" type="revolute">
       <parent link="Segment0"/>
       <child  link="Segment2"/>
       <origin rpy="0 0 0" xyz="-1.5 -1.0 1.5354513019656837" />
     <axis xyz="0 1 0"/>
       <limit effort="0.0" lower="-3.14159" upper="3.14159" velocity="0.0"/>
    </joint>
    <joint name="Segment0_Segment3" type="revolute">
       <parent link="Segment0"/>
       <child  link="Segment3"/>
       <origin rpy="0 0 0" xyz="1.5 -1.0 1.5680246315770823" />
     <axis xyz="0 1 0"/>
       <limit effort="0.0" lower="-3.14159" upper="3.14159" velocity="0.0"/>
    </joint>
    <joint name="Segment0_Segment4" type="revolute">
       <parent link="Segment0"/>
       <child  link="Segment4"/>
       <origin rpy="0 0 0" xyz="1.5 1.0 1.3573127180290783" />
     <axis xyz="0 1 0"/>
       <limit effort="0.0" lower="-3.14159" upper="3.14159" velocity="0.0"/>
    </joint>
    <link name="Segment1">
        <inertial>
            <origin xyz="0 0 0" rpy="0 0 0"/>
            <mass value="1" />
            <inertia ixx="100" ixy="0" ixz="0" iyy="100" iyz="0" izz="100" />
        </inertial>
        <visual>
            <origin xyz="0 0 0" rpy="0 0 0"/>
            <geometry>
                <box size="0.5791283281669375 0.9839385154019435 0.9393716233988043" />
            </geometry>
            <material name="Blue">
                <color rgba="0 0 1.0 1.0"/>
            </material>
        </visual>
        <collision>
            <origin xyz="0 0 0" rpy="0 0 0"/>
            <geometry>
                <box size="0.5791283281669375 0.9839385154019435 0.9393716233988043" />
            </geometry>
        </collision>
    </link>
    <joint name="Segment1_Segment5" type="revolute">
       <parent link="Segment1"/>
       <child  link="Segment5"/>
       <origin rpy="0 0 0" xyz="0.0 0.0 -0.7807662171027199" />
     <axis xyz="0 1 0"/>
       <limit effort="0.0" lower="-3.14159" upper="3.14159" velocity="0.0"/>
    </joint>
    <link name="Segment2">
        <inertial>
            <origin xyz="0 0 0" rpy="0 0 0"/>
            <mass value="1" />
            <inertia ixx="100" ixy="0" ixz="0" iyy="100" iyz="0" izz="100" />
        </inertial>
        <visual>
            <origin xyz="0 0 0" rpy="0 0 0"/>
            <geometry>
                <box size="0.878582981320488 0.9430983744391697 0.6917779291636981" />
            </geometry>
            <material name="Blue">
                <color rgba="0 0 1.0 1.0"/>
            </material>
        </visual>
        <collision>
            <origin xyz="0 0 0" rpy="0 0 0"/>
            <geometry>
                <box size="0.878582981320488 0.9430983744391697 0.6917779291636981" />
            </geometry>
        </collision>
    </link>
    <joint name="Segment2_Segment6" type="revolute">
       <parent link="Segment2"/>
       <child  link="Segment6"/>
       <origin rpy="0 0 0" xyz="0.0 -0.0 -0.8642758183551755" />
     <axis xyz="0 1 0"/>
       <limit effort="0.0" lower="-3.14159" upper="3.14159" velocity="0.0"/>
    </joint>
    <link name="Segment3">
        <inertial>
            <origin xyz="0 0 0" rpy="0 0 0"/>
            <mass value="1" />
            <inertia ixx="100" ixy="0" ixz="0" iyy="100" iyz="0" izz="100" />
        </inertial>
        <visual>
            <origin xyz="0 0 0" rpy="0 0 0"/>
            <geometry>
                <box size="0.4044493225472717 0.5144397666475639 0.626631269940901" />
            </geometry>
            <material name="Blue">
                <color rgba="0 0 1.0 1.0"/>
            </material>
        </visual>
        <collision>
            <origin xyz="0 0 0" rpy="0 0 0"/>
            <geometry>
                <box size="0.4044493225472717 0.5144397666475639 0.626631269940901" />
            </geometry>
        </collision>
    </link>
    <joint name="Segment3_Segment7" type="revolute">
       <parent link="Segment3"/>
       <child  link="Segment7"/>
       <origin rpy="0 0 0" xyz="0.0 0.0 -0.6914374634650657" />
     <axis xyz="0 1 0"/>
       <limit effort="0.0" lower="-3.14159" upper="3.14159" velocity="0.0"/>
    </joint>
    <link name="Segment4">
        <inertial>
            <origin xyz="0 0 0" rpy="0 0 0"/>
            <mass value="1" />
            <inertia ixx="100" ixy="0" ixz="0" iyy="100" iyz="0" izz="100" />
        </inertial>
        <visual>
            <origin xyz="0 0 0" rpy="0 0 0"/>
            <geometry>
                <box size="1.0352812174120398 0.5706440377403468 1.0480550970369091" />
            </geometry>
            <material name="Green">
                <color rgba="0 1.0 0 1.0"/>
            </material>
        </visual>
        <collision>
            <origin xyz="0 0 0" rpy="0 0 0"/>
            <geometry>
                <box size="1.0352812174120398 0.5706440377403468 1.0480550970369091" />
            </geometry>
        </collision>
    </link>
    <joint name="Segment4_Segment8" type="revolute">
       <parent link="Segment4"/>
       <child  link="Segment8"/>
       <origin rpy="0 0 0" xyz="0.0 -0.0 -0.735530900898338" />
     <axis xyz="0 1 0"/>
       <limit effort="0.0" lower="-3.14159" upper="3.14159" velocity="0.0"/>
    </joint>
    <link name="Segment5">
        <inertial>
            <origin xyz="0 0 0" rpy="0 0 0"/>
            <mass value="1" />
            <inertia ixx="100" ixy="0" ixz="0" iyy="100" iyz="0" izz="100" />
        </inertial>
        <visual>
            <origin xyz="0 0 0" rpy="0 0 0"/>
            <geometry>
                <box size="0.5868145458404233 0.40678507299798733 0.6221608108066353" />
            </geometry>
            <material name="Green">
                <color rgba="0 1.0 0 1.0"/>
            </material>
        </visual>
        <collision>
            <origin xyz="0 0 0" rpy="0 0 0"/>
            <geometry>
                <box size="0.5868145458404233 0.40678507299798733 0.6221608108066353" />
            </geometry>
        </collision>
    </link>
    <link name="Segment6">
        <inertial>
            <origin xyz="0 0 0" rpy="0 0 0"/>
            <mass value="1" />
            <inertia ixx="100" ixy="0" ixz="0" iyy="100" iyz="0" izz="100" />
        </inertial>
        <visual>
            <origin xyz="0 0 0" rpy="0 0 0"/>
            <geometry>
                <box size="0.8517141895143859 0.40049900935473165 1.036773707546653" />
            </geometry>
            <material name="Blue">
                <color rgba="0 0 1.0 1.0"/>
            </material>
        </visual>
        <collision>
            <origin xyz="0 0 0" rpy="0 0 0"/>
            <geometry>
                <box size="0.8517141895143859 0.40049900935473165 1.036773707546653" />
            </geometry>
        </collision>
    </link>
    <link name="Segment7">
        <inertial>
            <origin xyz="0 0 0" rpy="0 0 0"/>
            <mass value="1" />
            <inertia ixx="100" ixy="0" ixz="0" iyy="100" iyz="0" izz="100" />
        </inertial>
        <visual>
            <origin xyz="0 0 0" rpy="0 0 0"/>
            <geometry>
                <box size="0.48992839382830133 0.6672279316359142 0.7562436569892304" />
            </geometry>
            <material name="Green">
                <color rgba="0 1.0 0 1.0"/>
            </material>
        </visual>
        <collision>
            <origin xyz="0 0 0" rpy="0 0 0"/>
            <geometry>
                <box size="0.48992839382830133 0.6672279316359142 0.7562436569892304" />
            </geometry>
        </collision>
    </link>
    <link name="Segment8">
        <inertial>
            <origin xyz="0 0 0" rpy="0 0 0"/>
            <mass value="1" />
            <inertia ixx="100" ixy="0" ixz="0" iyy="100" iyz="0" izz="100" />
        </inertial>
        <visual>
            <origin xyz="0 0 0" rpy="0 0 0"/>
            <geometry>
                <box size="0.5276309892915962 0.6978818839932872 0.42300670475976676" />
            </geometry>
            <material name="Blue">
                <color rgba="0 0 1.0 1.0"/>
            </material>
        </visual>
        <collision>
            <origin xyz="0 0 0" rpy="0 0 0"/>
            <geometry>
                <box size="0.5276309892915962 0.6978818839932872 0.42300670475976676" />
            </geometry>
        </collision>
    </link>
</robot>