<robot name = "robot">
    <link name="Segment0">
        <inertial>
            <origin xyz="0 0 2.9660941306429955" rpy="0 0 0"/>
            <mass value="1" />
            <inertia ixx="100" ixy="0" ixz="0" iyy="100" iyz="0" izz="100" />
        </inertial>
        <visual>
            <origin xyz="0 0 2.9660941306429955" rpy="0 0 0"/>
            <geometry>
                <box size="3 2 1" />
            </geometry>
            <material name="Green">
                <color rgba="0 1.0 0 1.0"/>
            </material>
        </visual>
        <collision>
            <origin xyz="0 0 2.9660941306429955" rpy="0 0 0"/>
            <geometry>
                <box size="3 2 1" />
            </geometry>
        </collision>
    </link>
    <joint name="Segment0_Segment1" type="revolute">
       <parent link="Segment0"/>
       <child  link="Segment1"/>
       <origin rpy="0 0 0" xyz="-1.5 1.0 2.211970764684406" />
     <axis xyz="0 1 0"/>
       <limit effort="0.0" lower="-3.14159" upper="3.14159" velocity="0.0"/>
    </joint>
    <joint name="Segment0_Segment2" type="revolute">
       <parent link="Segment0"/>
       <child  link="Segment2"/>
       <origin rpy="0 0 0" xyz="-1.5 -1.0 2.1464457004819675" />
     <axis xyz="0 1 0"/>
       <limit effort="0.0" lower="-3.14159" upper="3.14159" velocity="0.0"/>
    </joint>
    <joint name="Segment0_Segment3" type="revolute">
       <parent link="Segment0"/>
       <child  link="Segment3"/>
       <origin rpy="0 0 0" xyz="1.5 -1.0 2.1544653082056717" />
     <axis xyz="0 1 0"/>
       <limit effort="0.0" lower="-3.14159" upper="3.14159" velocity="0.0"/>
    </joint>
    <joint name="Segment0_Segment4" type="revolute">
       <parent link="Segment0"/>
       <child  link="Segment4"/>
       <origin rpy="0 0 0" xyz="1.5 1.0 2.1054246401582493" />
     <axis xyz="0 1 0"/>
       <limit effort="0.0" lower="-3.14159" upper="3.14159" velocity="0.0"/>
    </joint>
    <link name="Segment1">
        <inertial>
            <origin xyz="0 0 0" rpy="0 0 0"/>
            <mass value="1" />
            <inertia ixx="100" ixy="0" ixz="0" iyy="100" iyz="0" izz="100" />
        </inertial>
        <visual>
            <origin xyz="0 0 0" rpy="0 0 0"/>
            <geometry>
                <box size="0.4228201286117672 0.5287796988687545 0.5082467319171792" />
            </geometry>
            <material name="Blue">
                <color rgba="0 0 1.0 1.0"/>
            </material>
        </visual>
        <collision>
            <origin xyz="0 0 0" rpy="0 0 0"/>
            <geometry>
                <box size="0.4228201286117672 0.5287796988687545 0.5082467319171792" />
            </geometry>
        </collision>
    </link>
    <joint name="Segment1_Segment5" type="revolute">
       <parent link="Segment1"/>
       <child  link="Segment5"/>
       <origin rpy="0 0 0" xyz="0.0 0.0 -0.7444514820269872" />
     <axis xyz="0 1 0"/>
       <limit effort="0.0" lower="-3.14159" upper="3.14159" velocity="0.0"/>
    </joint>
    <link name="Segment2">
        <inertial>
            <origin xyz="0 0 0" rpy="0 0 0"/>
            <mass value="1" />
            <inertia ixx="100" ixy="0" ixz="0" iyy="100" iyz="0" izz="100" />
        </inertial>
        <visual>
            <origin xyz="0 0 0" rpy="0 0 0"/>
            <geometry>
                <box size="0.5506123833403024 0.5496401107243161 0.6392968603220557" />
            </geometry>
            <material name="Blue">
                <color rgba="0 0 1.0 1.0"/>
            </material>
        </visual>
        <collision>
            <origin xyz="0 0 0" rpy="0 0 0"/>
            <geometry>
                <box size="0.5506123833403024 0.5496401107243161 0.6392968603220557" />
            </geometry>
        </collision>
    </link>
    <joint name="Segment2_Segment6" type="revolute">
       <parent link="Segment2"/>
       <child  link="Segment6"/>
       <origin rpy="0 0 0" xyz="0.0 -0.0 -0.5512418190748999" />
     <axis xyz="0 1 0"/>
       <limit effort="0.0" lower="-3.14159" upper="3.14159" velocity="0.0"/>
    </joint>
    <link name="Segment3">
        <inertial>
            <origin xyz="0 0 0" rpy="0 0 0"/>
            <mass value="1" />
            <inertia ixx="100" ixy="0" ixz="0" iyy="100" iyz="0" izz="100" />
        </inertial>
        <visual>
            <origin xyz="0 0 0" rpy="0 0 0"/>
            <geometry>
                <box size="0.6773027600729558 0.5605417252887461 0.6232576448746477" />
            </geometry>
            <material name="Blue">
                <color rgba="0 0 1.0 1.0"/>
            </material>
        </visual>
        <collision>
            <origin xyz="0 0 0" rpy="0 0 0"/>
            <geometry>
                <box size="0.6773027600729558 0.5605417252887461 0.6232576448746477" />
            </geometry>
        </collision>
    </link>
    <joint name="Segment3_Segment7" type="revolute">
       <parent link="Segment3"/>
       <child  link="Segment7"/>
       <origin rpy="0 0 0" xyz="0.0 0.0 -0.7016835511242199" />
     <axis xyz="0 1 0"/>
       <limit effort="0.0" lower="-3.14159" upper="3.14159" velocity="0.0"/>
    </joint>
    <link name="Segment4">
        <inertial>
            <origin xyz="0 0 0" rpy="0 0 0"/>
            <mass value="1" />
            <inertia ixx="100" ixy="0" ixz="0" iyy="100" iyz="0" izz="100" />
        </inertial>
        <visual>
            <origin xyz="0 0 0" rpy="0 0 0"/>
            <geometry>
                <box size="0.7308698505416631 0.5298850457515993 0.7213389809694928" />
            </geometry>
            <material name="Green">
                <color rgba="0 1.0 0 1.0"/>
            </material>
        </visual>
        <collision>
            <origin xyz="0 0 0" rpy="0 0 0"/>
            <geometry>
                <box size="0.7308698505416631 0.5298850457515993 0.7213389809694928" />
            </geometry>
        </collision>
    </link>
    <joint name="Segment4_Segment8" type="revolute">
       <parent link="Segment4"/>
       <child  link="Segment8"/>
       <origin rpy="0 0 0" xyz="0.0 -0.0 -0.6058072585152897" />
     <axis xyz="0 1 0"/>
       <limit effort="0.0" lower="-3.14159" upper="3.14159" velocity="0.0"/>
    </joint>
    <link name="Segment5">
        <inertial>
            <origin xyz="0 0 0" rpy="0 0 0"/>
            <mass value="1" />
            <inertia ixx="100" ixy="0" ixz="0" iyy="100" iyz="0" izz="100" />
        </inertial>
        <visual>
            <origin xyz="0 0 0" rpy="0 0 0"/>
            <geometry>
                <box size="0.5810443303873092 0.7960905894183693 0.9806562321367952" />
            </geometry>
            <material name="Blue">
                <color rgba="0 0 1.0 1.0"/>
            </material>
        </visual>
        <collision>
            <origin xyz="0 0 0" rpy="0 0 0"/>
            <geometry>
                <box size="0.5810443303873092 0.7960905894183693 0.9806562321367952" />
            </geometry>
        </collision>
    </link>
    <joint name="Segment5_Segment9" type="revolute">
       <parent link="Segment5"/>
       <child  link="Segment9"/>
       <origin rpy="0 0 0" xyz="0.0 0.0 -0.7093169157607064" />
     <axis xyz="0 1 0"/>
       <limit effort="0.0" lower="-3.14159" upper="3.14159" velocity="0.0"/>
    </joint>
    <link name="Segment6">
        <inertial>
            <origin xyz="0 0 0" rpy="0 0 0"/>
            <mass value="1" />
            <inertia ixx="100" ixy="0" ixz="0" iyy="100" iyz="0" izz="100" />
        </inertial>
        <visual>
            <origin xyz="0 0 0" rpy="0 0 0"/>
            <geometry>
                <box size="0.8346195013043645 0.4981518431213365 0.46318677782774414" />
            </geometry>
            <material name="Blue">
                <color rgba="0 0 1.0 1.0"/>
            </material>
        </visual>
        <collision>
            <origin xyz="0 0 0" rpy="0 0 0"/>
            <geometry>
                <box size="0.8346195013043645 0.4981518431213365 0.46318677782774414" />
            </geometry>
        </collision>
    </link>
    <joint name="Segment6_Segment10" type="revolute">
       <parent link="Segment6"/>
       <child  link="Segment10"/>
       <origin rpy="0 0 0" xyz="0.0 -0.0 -0.5517452583389394" />
     <axis xyz="0 1 0"/>
       <limit effort="0.0" lower="-3.14159" upper="3.14159" velocity="0.0"/>
    </joint>
    <link name="Segment7">
        <inertial>
            <origin xyz="0 0 0" rpy="0 0 0"/>
            <mass value="1" />
            <inertia ixx="100" ixy="0" ixz="0" iyy="100" iyz="0" izz="100" />
        </inertial>
        <visual>
            <origin xyz="0 0 0" rpy="0 0 0"/>
            <geometry>
                <box size="0.7144820208195336 0.7681358119107173 0.780109457373792" />
            </geometry>
            <material name="Green">
                <color rgba="0 1.0 0 1.0"/>
            </material>
        </visual>
        <collision>
            <origin xyz="0 0 0" rpy="0 0 0"/>
            <geometry>
                <box size="0.7144820208195336 0.7681358119107173 0.780109457373792" />
            </geometry>
        </collision>
    </link>
    <joint name="Segment7_Segment11" type="revolute">
       <parent link="Segment7"/>
       <child  link="Segment11"/>
       <origin rpy="0 0 0" xyz="0.0 0.0 -0.7075340470735936" />
     <axis xyz="0 1 0"/>
       <limit effort="0.0" lower="-3.14159" upper="3.14159" velocity="0.0"/>
    </joint>
    <link name="Segment8">
        <inertial>
            <origin xyz="0 0 0" rpy="0 0 0"/>
            <mass value="1" />
            <inertia ixx="100" ixy="0" ixz="0" iyy="100" iyz="0" izz="100" />
        </inertial>
        <visual>
            <origin xyz="0 0 0" rpy="0 0 0"/>
            <geometry>
                <box size="0.48020621639586814 0.7070247334580719 0.4902755360610866" />
            </geometry>
            <material name="Blue">
                <color rgba="0 0 1.0 1.0"/>
            </material>
        </visual>
        <collision>
            <origin xyz="0 0 0" rpy="0 0 0"/>
            <geometry>
                <box size="0.48020621639586814 0.7070247334580719 0.4902755360610866" />
            </geometry>
        </collision>
    </link>
    <joint name="Segment8_Segment12" type="revolute">
       <parent link="Segment8"/>
       <child  link="Segment12"/>
       <origin rpy="0 0 0" xyz="0.0 -0.0 -0.7344748657495666" />
     <axis xyz="0 1 0"/>
       <limit effort="0.0" lower="-3.14159" upper="3.14159" velocity="0.0"/>
    </joint>
    <link name="Segment9">
        <inertial>
            <origin xyz="0 0 0" rpy="0 0 0"/>
            <mass value="1" />
            <inertia ixx="100" ixy="0" ixz="0" iyy="100" iyz="0" izz="100" />
        </inertial>
        <visual>
            <origin xyz="0 0 0" rpy="0 0 0"/>
            <geometry>
                <box size="0.6986418857755923 0.437651795227914 0.43797759938461756" />
            </geometry>
            <material name="Blue">
                <color rgba="0 0 1.0 1.0"/>
            </material>
        </visual>
        <collision>
            <origin xyz="0 0 0" rpy="0 0 0"/>
            <geometry>
                <box size="0.6986418857755923 0.437651795227914 0.43797759938461756" />
            </geometry>
        </collision>
    </link>
    <link name="Segment10">
        <inertial>
            <origin xyz="0 0 0" rpy="0 0 0"/>
            <mass value="1" />
            <inertia ixx="100" ixy="0" ixz="0" iyy="100" iyz="0" izz="100" />
        </inertial>
        <visual>
            <origin xyz="0 0 0" rpy="0 0 0"/>
            <geometry>
                <box size="0.4134233736718544 0.5565476718688966 0.6403037388501347" />
            </geometry>
            <material name="Blue">
                <color rgba="0 0 1.0 1.0"/>
            </material>
        </visual>
        <collision>
            <origin xyz="0 0 0" rpy="0 0 0"/>
            <geometry>
                <box size="0.4134233736718544 0.5565476718688966 0.6403037388501347" />
            </geometry>
        </collision>
    </link>
    <link name="Segment11">
        <inertial>
            <origin xyz="0 0 0" rpy="0 0 0"/>
            <mass value="1" />
            <inertia ixx="100" ixy="0" ixz="0" iyy="100" iyz="0" izz="100" />
        </inertial>
        <visual>
            <origin xyz="0 0 0" rpy="0 0 0"/>
            <geometry>
                <box size="0.6199631133307536 0.7074727951674524 0.6349586367733953" />
            </geometry>
            <material name="Green">
                <color rgba="0 1.0 0 1.0"/>
            </material>
        </visual>
        <collision>
            <origin xyz="0 0 0" rpy="0 0 0"/>
            <geometry>
                <box size="0.6199631133307536 0.7074727951674524 0.6349586367733953" />
            </geometry>
        </collision>
    </link>
    <link name="Segment12">
        <inertial>
            <origin xyz="0 0 0" rpy="0 0 0"/>
            <mass value="1" />
            <inertia ixx="100" ixy="0" ixz="0" iyy="100" iyz="0" izz="100" />
        </inertial>
        <visual>
            <origin xyz="0 0 0" rpy="0 0 0"/>
            <geometry>
                <box size="0.8195939072181939 0.7898484813149738 0.9786741954380465" />
            </geometry>
            <material name="Blue">
                <color rgba="0 0 1.0 1.0"/>
            </material>
        </visual>
        <collision>
            <origin xyz="0 0 0" rpy="0 0 0"/>
            <geometry>
                <box size="0.8195939072181939 0.7898484813149738 0.9786741954380465" />
            </geometry>
        </collision>
    </link>
</robot>