<robot name = "robot">
    <link name="Segment0">
        <inertial>
            <origin xyz="0 0 7.7711288002883" rpy="0 0 0"/>
            <mass value="1" />
            <inertia ixx="100" ixy="0" ixz="0" iyy="100" iyz="0" izz="100" />
        </inertial>
        <visual>
            <origin xyz="0 0 7.7711288002883" rpy="0 0 0"/>
            <geometry>
                <box size="1.2227375255694746 1.4188719473436937 1.2112965306504988" />
            </geometry>
            <material name="Blue">
                <color rgba="0 0 1.0 1.0"/>
            </material>
        </visual>
        <collision>
            <origin xyz="0 0 7.7711288002883" rpy="0 0 0"/>
            <geometry>
                <box size="1.2227375255694746 1.4188719473436937 1.2112965306504988" />
            </geometry>
        </collision>
    </link>
    <joint name="Segment0_Segment1" type="revolute">
       <parent link="Segment0"/>
       <child  link="Segment1"/>
       <origin rpy="0 0 0" xyz="-0.6113687627847373 0.7094359736718469 7.468304667625675" />
     <axis xyz="0 1 1"/>
       <limit effort="0.0" lower="-3.14159" upper="3.14159" velocity="0.0"/>
    </joint>
    <joint name="Segment0_Segment2" type="revolute">
       <parent link="Segment0"/>
       <child  link="Segment2"/>
       <origin rpy="0 0 0" xyz="-0.6113687627847373 -0.7094359736718469 7.468304667625675" />
     <axis xyz="0 1 1"/>
       <limit effort="0.0" lower="-3.14159" upper="3.14159" velocity="0.0"/>
    </joint>
    <link name="Segment1">
        <inertial>
            <origin xyz="0.5898323169394459 0.5958504448196479 -0.385072909770204" rpy="0 0 0"/>
            <mass value="1" />
            <inertia ixx="100" ixy="0" ixz="0" iyy="100" iyz="0" izz="100" />
        </inertial>
        <visual>
            <origin xyz="0.5898323169394459 0.5958504448196479 -0.385072909770204" rpy="0 0 0"/>
            <geometry>
                <box size="1.1796646338788919 1.1917008896392958 1.540291639080816" />
            </geometry>
            <material name="Green">
                <color rgba="0 1.0 0 1.0"/>
            </material>
        </visual>
        <collision>
            <origin xyz="0.5898323169394459 0.5958504448196479 -0.385072909770204" rpy="0 0 0"/>
            <geometry>
                <box size="1.1796646338788919 1.1917008896392958 1.540291639080816" />
            </geometry>
        </collision>
    </link>
    <joint name="Segment1_Segment3" type="revolute">
       <parent link="Segment1"/>
       <child  link="Segment3"/>
       <origin rpy="0 0 0" xyz="0.0 0.0 -1.540291639080816" />
     <axis xyz="0 1 1"/>
       <limit effort="0.0" lower="-3.14159" upper="3.14159" velocity="0.0"/>
    </joint>
    <link name="Segment2">
        <inertial>
            <origin xyz="0.6706747951061414 -0.6803858497221943 -0.31013294701407335" rpy="0 0 0"/>
            <mass value="1" />
            <inertia ixx="100" ixy="0" ixz="0" iyy="100" iyz="0" izz="100" />
        </inertial>
        <visual>
            <origin xyz="0.6706747951061414 -0.6803858497221943 -0.31013294701407335" rpy="0 0 0"/>
            <geometry>
                <box size="1.3413495902122827 1.3607716994443886 1.2405317880562934" />
            </geometry>
            <material name="Blue">
                <color rgba="0 0 1.0 1.0"/>
            </material>
        </visual>
        <collision>
            <origin xyz="0.6706747951061414 -0.6803858497221943 -0.31013294701407335" rpy="0 0 0"/>
            <geometry>
                <box size="1.3413495902122827 1.3607716994443886 1.2405317880562934" />
            </geometry>
        </collision>
    </link>
    <joint name="Segment2_Segment4" type="revolute">
       <parent link="Segment2"/>
       <child  link="Segment4"/>
       <origin rpy="0 0 0" xyz="0.6803858497221943 -0.6803858497221943 -1.2405317880562934" />
     <axis xyz="0 1 1"/>
       <limit effort="0.0" lower="-3.14159" upper="3.14159" velocity="0.0"/>
    </joint>
    <link name="Segment3">
        <inertial>
            <origin xyz="0.8607368657604961 0.8986859661446476 -0.4397782510506632" rpy="0 0 0"/>
            <mass value="1" />
            <inertia ixx="100" ixy="0" ixz="0" iyy="100" iyz="0" izz="100" />
        </inertial>
        <visual>
            <origin xyz="0.8607368657604961 0.8986859661446476 -0.4397782510506632" rpy="0 0 0"/>
            <geometry>
                <box size="1.7214737315209923 1.7973719322892951 1.7591130042026528" />
            </geometry>
            <material name="Blue">
                <color rgba="0 0 1.0 1.0"/>
            </material>
        </visual>
        <collision>
            <origin xyz="0.8607368657604961 0.8986859661446476 -0.4397782510506632" rpy="0 0 0"/>
            <geometry>
                <box size="1.7214737315209923 1.7973719322892951 1.7591130042026528" />
            </geometry>
        </collision>
    </link>
    <joint name="Segment3_Segment5" type="revolute">
       <parent link="Segment3"/>
       <child  link="Segment5"/>
       <origin rpy="0 0 0" xyz="0.8986859661446476 0.0 -1.7591130042026528" />
     <axis xyz="0 1 1"/>
       <limit effort="0.0" lower="-3.14159" upper="3.14159" velocity="0.0"/>
    </joint>
    <link name="Segment4">
        <inertial>
            <origin xyz="0.6119865025577234 -0.9323100259427471 -0.3272966840399455" rpy="0 0 0"/>
            <mass value="1" />
            <inertia ixx="100" ixy="0" ixz="0" iyy="100" iyz="0" izz="100" />
        </inertial>
        <visual>
            <origin xyz="0.6119865025577234 -0.9323100259427471 -0.3272966840399455" rpy="0 0 0"/>
            <geometry>
                <box size="1.2239730051154467 1.8646200518854943 1.309186736159782" />
            </geometry>
            <material name="Blue">
                <color rgba="0 0 1.0 1.0"/>
            </material>
        </visual>
        <collision>
            <origin xyz="0.6119865025577234 -0.9323100259427471 -0.3272966840399455" rpy="0 0 0"/>
            <geometry>
                <box size="1.2239730051154467 1.8646200518854943 1.309186736159782" />
            </geometry>
        </collision>
    </link>
    <joint name="Segment4_Segment6" type="revolute">
       <parent link="Segment4"/>
       <child  link="Segment6"/>
       <origin rpy="0 0 0" xyz="0.9323100259427471 -0.9323100259427471 -1.309186736159782" />
     <axis xyz="0 1 1"/>
       <limit effort="0.0" lower="-3.14159" upper="3.14159" velocity="0.0"/>
    </joint>
    <link name="Segment5">
        <inertial>
            <origin xyz="0.8110799627881726 0.5124874376344871 -0.3612992969848957" rpy="0 0 0"/>
            <mass value="1" />
            <inertia ixx="100" ixy="0" ixz="0" iyy="100" iyz="0" izz="100" />
        </inertial>
        <visual>
            <origin xyz="0.8110799627881726 0.5124874376344871 -0.3612992969848957" rpy="0 0 0"/>
            <geometry>
                <box size="1.6221599255763453 1.0249748752689742 1.4451971879395829" />
            </geometry>
            <material name="Blue">
                <color rgba="0 0 1.0 1.0"/>
            </material>
        </visual>
        <collision>
            <origin xyz="0.8110799627881726 0.5124874376344871 -0.3612992969848957" rpy="0 0 0"/>
            <geometry>
                <box size="1.6221599255763453 1.0249748752689742 1.4451971879395829" />
            </geometry>
        </collision>
    </link>
    <joint name="Segment5_Segment7" type="revolute">
       <parent link="Segment5"/>
       <child  link="Segment7"/>
       <origin rpy="0 0 0" xyz="0.0 0.5124874376344871 -1.4451971879395829" />
     <axis xyz="0 1 1"/>
       <limit effort="0.0" lower="-3.14159" upper="3.14159" velocity="0.0"/>
    </joint>
    <link name="Segment6">
        <inertial>
            <origin xyz="0.6995687520965503 -0.9357906742930662 -0.38895409857076" rpy="0 0 0"/>
            <mass value="1" />
            <inertia ixx="100" ixy="0" ixz="0" iyy="100" iyz="0" izz="100" />
        </inertial>
        <visual>
            <origin xyz="0.6995687520965503 -0.9357906742930662 -0.38895409857076" rpy="0 0 0"/>
            <geometry>
                <box size="1.3991375041931007 1.8715813485861323 1.55581639428304" />
            </geometry>
            <material name="Green">
                <color rgba="0 1.0 0 1.0"/>
            </material>
        </visual>
        <collision>
            <origin xyz="0.6995687520965503 -0.9357906742930662 -0.38895409857076" rpy="0 0 0"/>
            <geometry>
                <box size="1.3991375041931007 1.8715813485861323 1.55581639428304" />
            </geometry>
        </collision>
    </link>
    <joint name="Segment6_Segment8" type="revolute">
       <parent link="Segment6"/>
       <child  link="Segment8"/>
       <origin rpy="0 0 0" xyz="0.0 -0.0 -1.55581639428304" />
     <axis xyz="0 1 1"/>
       <limit effort="0.0" lower="-3.14159" upper="3.14159" velocity="0.0"/>
    </joint>
    <link name="Segment7">
        <inertial>
            <origin xyz="0.683751178034276 0.638161611738691 -0.3337133146444188" rpy="0 0 0"/>
            <mass value="1" />
            <inertia ixx="100" ixy="0" ixz="0" iyy="100" iyz="0" izz="100" />
        </inertial>
        <visual>
            <origin xyz="0.683751178034276 0.638161611738691 -0.3337133146444188" rpy="0 0 0"/>
            <geometry>
                <box size="1.367502356068552 1.276323223477382 1.3348532585776751" />
            </geometry>
            <material name="Blue">
                <color rgba="0 0 1.0 1.0"/>
            </material>
        </visual>
        <collision>
            <origin xyz="0.683751178034276 0.638161611738691 -0.3337133146444188" rpy="0 0 0"/>
            <geometry>
                <box size="1.367502356068552 1.276323223477382 1.3348532585776751" />
            </geometry>
        </collision>
    </link>
    <joint name="Segment7_Segment9" type="revolute">
       <parent link="Segment7"/>
       <child  link="Segment9"/>
       <origin rpy="0 0 0" xyz="0.638161611738691 0.0 -1.3348532585776751" />
     <axis xyz="0 1 1"/>
       <limit effort="0.0" lower="-3.14159" upper="3.14159" velocity="0.0"/>
    </joint>
    <link name="Segment8">
        <inertial>
            <origin xyz="0.6843865372416567 -0.6620986654366657 -0.3717061818201681" rpy="0 0 0"/>
            <mass value="1" />
            <inertia ixx="100" ixy="0" ixz="0" iyy="100" iyz="0" izz="100" />
        </inertial>
        <visual>
            <origin xyz="0.6843865372416567 -0.6620986654366657 -0.3717061818201681" rpy="0 0 0"/>
            <geometry>
                <box size="1.3687730744833133 1.3241973308733315 1.4868247272806725" />
            </geometry>
            <material name="Blue">
                <color rgba="0 0 1.0 1.0"/>
            </material>
        </visual>
        <collision>
            <origin xyz="0.6843865372416567 -0.6620986654366657 -0.3717061818201681" rpy="0 0 0"/>
            <geometry>
                <box size="1.3687730744833133 1.3241973308733315 1.4868247272806725" />
            </geometry>
        </collision>
    </link>
    <joint name="Segment8_Segment10" type="revolute">
       <parent link="Segment8"/>
       <child  link="Segment10"/>
       <origin rpy="0 0 0" xyz="0.0 -0.6620986654366657 -1.4868247272806725" />
     <axis xyz="0 1 1"/>
       <limit effort="0.0" lower="-3.14159" upper="3.14159" velocity="0.0"/>
    </joint>
    <link name="Segment9">
        <inertial>
            <origin xyz="0.9226900910035007 0.7335809773124704 -0.35631197533721054" rpy="0 0 0"/>
            <mass value="1" />
            <inertia ixx="100" ixy="0" ixz="0" iyy="100" iyz="0" izz="100" />
        </inertial>
        <visual>
            <origin xyz="0.9226900910035007 0.7335809773124704 -0.35631197533721054" rpy="0 0 0"/>
            <geometry>
                <box size="1.8453801820070015 1.4671619546249408 1.4252479013488422" />
            </geometry>
            <material name="Blue">
                <color rgba="0 0 1.0 1.0"/>
            </material>
        </visual>
        <collision>
            <origin xyz="0.9226900910035007 0.7335809773124704 -0.35631197533721054" rpy="0 0 0"/>
            <geometry>
                <box size="1.8453801820070015 1.4671619546249408 1.4252479013488422" />
            </geometry>
        </collision>
    </link>
    <link name="Segment10">
        <inertial>
            <origin xyz="0.6452951457016265 -0.6517988823099244 -0.3084746082491866" rpy="0 0 0"/>
            <mass value="1" />
            <inertia ixx="100" ixy="0" ixz="0" iyy="100" iyz="0" izz="100" />
        </inertial>
        <visual>
            <origin xyz="0.6452951457016265 -0.6517988823099244 -0.3084746082491866" rpy="0 0 0"/>
            <geometry>
                <box size="1.290590291403253 1.3035977646198489 1.2338984329967464" />
            </geometry>
            <material name="Blue">
                <color rgba="0 0 1.0 1.0"/>
            </material>
        </visual>
        <collision>
            <origin xyz="0.6452951457016265 -0.6517988823099244 -0.3084746082491866" rpy="0 0 0"/>
            <geometry>
                <box size="1.290590291403253 1.3035977646198489 1.2338984329967464" />
            </geometry>
        </collision>
    </link>
</robot>