<robot name = "robot">
    <link name="Segment0">
        <inertial>
            <origin xyz="0 0 7.4500968915779975" rpy="0 0 0"/>
            <mass value="1" />
            <inertia ixx="100" ixy="0" ixz="0" iyy="100" iyz="0" izz="100" />
        </inertial>
        <visual>
            <origin xyz="0 0 7.4500968915779975" rpy="0 0 0"/>
            <geometry>
                <box size="1.4567813940615606 1.134319541754019 1.0402946828618573" />
            </geometry>
            <material name="Blue">
                <color rgba="0 0 1.0 1.0"/>
            </material>
        </visual>
        <collision>
            <origin xyz="0 0 7.4500968915779975" rpy="0 0 0"/>
            <geometry>
                <box size="1.4567813940615606 1.134319541754019 1.0402946828618573" />
            </geometry>
        </collision>
    </link>
    <joint name="Segment0_Segment1" type="revolute">
       <parent link="Segment0"/>
       <child  link="Segment1"/>
       <origin rpy="0 0 0" xyz="-0.7283906970307803 0.5671597708770095 7.190023220862533" />
     <axis xyz="0 1 1"/>
       <limit effort="0.0" lower="-3.14159" upper="3.14159" velocity="0.0"/>
    </joint>
    <joint name="Segment0_Segment2" type="revolute">
       <parent link="Segment0"/>
       <child  link="Segment2"/>
       <origin rpy="0 0 0" xyz="-0.7283906970307803 -0.5671597708770095 7.190023220862533" />
     <axis xyz="0 1 1"/>
       <limit effort="0.0" lower="-3.14159" upper="3.14159" velocity="0.0"/>
    </joint>
    <link name="Segment1">
        <inertial>
            <origin xyz="0.5297002963500869 0.723123664419983 -0.31192901629949554" rpy="0 0 0"/>
            <mass value="1" />
            <inertia ixx="100" ixy="0" ixz="0" iyy="100" iyz="0" izz="100" />
        </inertial>
        <visual>
            <origin xyz="0.5297002963500869 0.723123664419983 -0.31192901629949554" rpy="0 0 0"/>
            <geometry>
                <box size="1.0594005927001737 1.446247328839966 1.2477160651979822" />
            </geometry>
            <material name="Green">
                <color rgba="0 1.0 0 1.0"/>
            </material>
        </visual>
        <collision>
            <origin xyz="0.5297002963500869 0.723123664419983 -0.31192901629949554" rpy="0 0 0"/>
            <geometry>
                <box size="1.0594005927001737 1.446247328839966 1.2477160651979822" />
            </geometry>
        </collision>
    </link>
    <joint name="Segment1_Segment3" type="revolute">
       <parent link="Segment1"/>
       <child  link="Segment3"/>
       <origin rpy="0 0 0" xyz="0.0 0.0 -1.2477160651979822" />
     <axis xyz="0 1 1"/>
       <limit effort="0.0" lower="-3.14159" upper="3.14159" velocity="0.0"/>
    </joint>
    <link name="Segment2">
        <inertial>
            <origin xyz="0.7310544171882548 -0.5153608665700449 -0.334379803155288" rpy="0 0 0"/>
            <mass value="1" />
            <inertia ixx="100" ixy="0" ixz="0" iyy="100" iyz="0" izz="100" />
        </inertial>
        <visual>
            <origin xyz="0.7310544171882548 -0.5153608665700449 -0.334379803155288" rpy="0 0 0"/>
            <geometry>
                <box size="1.4621088343765096 1.0307217331400897 1.337519212621152" />
            </geometry>
            <material name="Blue">
                <color rgba="0 0 1.0 1.0"/>
            </material>
        </visual>
        <collision>
            <origin xyz="0.7310544171882548 -0.5153608665700449 -0.334379803155288" rpy="0 0 0"/>
            <geometry>
                <box size="1.4621088343765096 1.0307217331400897 1.337519212621152" />
            </geometry>
        </collision>
    </link>
    <joint name="Segment2_Segment4" type="revolute">
       <parent link="Segment2"/>
       <child  link="Segment4"/>
       <origin rpy="0 0 0" xyz="0.5153608665700449 -0.0 -1.337519212621152" />
     <axis xyz="0 1 1"/>
       <limit effort="0.0" lower="-3.14159" upper="3.14159" velocity="0.0"/>
    </joint>
    <link name="Segment3">
        <inertial>
            <origin xyz="0.6954285690457026 0.6375451602760781 -0.37296490707700436" rpy="0 0 0"/>
            <mass value="1" />
            <inertia ixx="100" ixy="0" ixz="0" iyy="100" iyz="0" izz="100" />
        </inertial>
        <visual>
            <origin xyz="0.6954285690457026 0.6375451602760781 -0.37296490707700436" rpy="0 0 0"/>
            <geometry>
                <box size="1.3908571380914052 1.2750903205521562 1.4918596283080174" />
            </geometry>
            <material name="Blue">
                <color rgba="0 0 1.0 1.0"/>
            </material>
        </visual>
        <collision>
            <origin xyz="0.6954285690457026 0.6375451602760781 -0.37296490707700436" rpy="0 0 0"/>
            <geometry>
                <box size="1.3908571380914052 1.2750903205521562 1.4918596283080174" />
            </geometry>
        </collision>
    </link>
    <joint name="Segment3_Segment5" type="revolute">
       <parent link="Segment3"/>
       <child  link="Segment5"/>
       <origin rpy="0 0 0" xyz="0.6375451602760781 0.0 -1.4918596283080174" />
     <axis xyz="0 1 1"/>
       <limit effort="0.0" lower="-3.14159" upper="3.14159" velocity="0.0"/>
    </joint>
    <link name="Segment4">
        <inertial>
            <origin xyz="0.6421434727572304 -0.5444409214642003 -0.34160048284118605" rpy="0 0 0"/>
            <mass value="1" />
            <inertia ixx="100" ixy="0" ixz="0" iyy="100" iyz="0" izz="100" />
        </inertial>
        <visual>
            <origin xyz="0.6421434727572304 -0.5444409214642003 -0.34160048284118605" rpy="0 0 0"/>
            <geometry>
                <box size="1.2842869455144608 1.0888818429284006 1.3664019313647442" />
            </geometry>
            <material name="Blue">
                <color rgba="0 0 1.0 1.0"/>
            </material>
        </visual>
        <collision>
            <origin xyz="0.6421434727572304 -0.5444409214642003 -0.34160048284118605" rpy="0 0 0"/>
            <geometry>
                <box size="1.2842869455144608 1.0888818429284006 1.3664019313647442" />
            </geometry>
        </collision>
    </link>
    <joint name="Segment4_Segment6" type="revolute">
       <parent link="Segment4"/>
       <child  link="Segment6"/>
       <origin rpy="0 0 0" xyz="0.5444409214642003 -0.5444409214642003 -1.3664019313647442" />
     <axis xyz="0 1 1"/>
       <limit effort="0.0" lower="-3.14159" upper="3.14159" velocity="0.0"/>
    </joint>
    <link name="Segment5">
        <inertial>
            <origin xyz="0.6028324879298012 0.5767667459383147 -0.42659666252190037" rpy="0 0 0"/>
            <mass value="1" />
            <inertia ixx="100" ixy="0" ixz="0" iyy="100" iyz="0" izz="100" />
        </inertial>
        <visual>
            <origin xyz="0.6028324879298012 0.5767667459383147 -0.42659666252190037" rpy="0 0 0"/>
            <geometry>
                <box size="1.2056649758596023 1.1535334918766293 1.7063866500876015" />
            </geometry>
            <material name="Blue">
                <color rgba="0 0 1.0 1.0"/>
            </material>
        </visual>
        <collision>
            <origin xyz="0.6028324879298012 0.5767667459383147 -0.42659666252190037" rpy="0 0 0"/>
            <geometry>
                <box size="1.2056649758596023 1.1535334918766293 1.7063866500876015" />
            </geometry>
        </collision>
    </link>
    <joint name="Segment5_Segment7" type="revolute">
       <parent link="Segment5"/>
       <child  link="Segment7"/>
       <origin rpy="0 0 0" xyz="0.5767667459383147 0.5767667459383147 -1.7063866500876015" />
     <axis xyz="0 1 1"/>
       <limit effort="0.0" lower="-3.14159" upper="3.14159" velocity="0.0"/>
    </joint>
    <link name="Segment6">
        <inertial>
            <origin xyz="0.7388864202648441 -0.911698184638803 -0.33716923195514537" rpy="0 0 0"/>
            <mass value="1" />
            <inertia ixx="100" ixy="0" ixz="0" iyy="100" iyz="0" izz="100" />
        </inertial>
        <visual>
            <origin xyz="0.7388864202648441 -0.911698184638803 -0.33716923195514537" rpy="0 0 0"/>
            <geometry>
                <box size="1.4777728405296882 1.823396369277606 1.3486769278205815" />
            </geometry>
            <material name="Green">
                <color rgba="0 1.0 0 1.0"/>
            </material>
        </visual>
        <collision>
            <origin xyz="0.7388864202648441 -0.911698184638803 -0.33716923195514537" rpy="0 0 0"/>
            <geometry>
                <box size="1.4777728405296882 1.823396369277606 1.3486769278205815" />
            </geometry>
        </collision>
    </link>
    <joint name="Segment6_Segment8" type="revolute">
       <parent link="Segment6"/>
       <child  link="Segment8"/>
       <origin rpy="0 0 0" xyz="0.911698184638803 -0.0 -1.3486769278205815" />
     <axis xyz="0 1 1"/>
       <limit effort="0.0" lower="-3.14159" upper="3.14159" velocity="0.0"/>
    </joint>
    <link name="Segment7">
        <inertial>
            <origin xyz="0.7241267963602204 0.5382761623416881 -0.4352874015336372" rpy="0 0 0"/>
            <mass value="1" />
            <inertia ixx="100" ixy="0" ixz="0" iyy="100" iyz="0" izz="100" />
        </inertial>
        <visual>
            <origin xyz="0.7241267963602204 0.5382761623416881 -0.4352874015336372" rpy="0 0 0"/>
            <geometry>
                <box size="1.4482535927204407 1.0765523246833761 1.7411496061345488" />
            </geometry>
            <material name="Blue">
                <color rgba="0 0 1.0 1.0"/>
            </material>
        </visual>
        <collision>
            <origin xyz="0.7241267963602204 0.5382761623416881 -0.4352874015336372" rpy="0 0 0"/>
            <geometry>
                <box size="1.4482535927204407 1.0765523246833761 1.7411496061345488" />
            </geometry>
        </collision>
    </link>
    <joint name="Segment7_Segment9" type="revolute">
       <parent link="Segment7"/>
       <child  link="Segment9"/>
       <origin rpy="0 0 0" xyz="0.0 0.0 -1.7411496061345488" />
     <axis xyz="0 1 1"/>
       <limit effort="0.0" lower="-3.14159" upper="3.14159" velocity="0.0"/>
    </joint>
    <link name="Segment8">
        <inertial>
            <origin xyz="0.6161654997297413 -0.7388271586659254 -0.25560193819870036" rpy="0 0 0"/>
            <mass value="1" />
            <inertia ixx="100" ixy="0" ixz="0" iyy="100" iyz="0" izz="100" />
        </inertial>
        <visual>
            <origin xyz="0.6161654997297413 -0.7388271586659254 -0.25560193819870036" rpy="0 0 0"/>
            <geometry>
                <box size="1.2323309994594827 1.4776543173318508 1.0224077527948014" />
            </geometry>
            <material name="Blue">
                <color rgba="0 0 1.0 1.0"/>
            </material>
        </visual>
        <collision>
            <origin xyz="0.6161654997297413 -0.7388271586659254 -0.25560193819870036" rpy="0 0 0"/>
            <geometry>
                <box size="1.2323309994594827 1.4776543173318508 1.0224077527948014" />
            </geometry>
        </collision>
    </link>
    <joint name="Segment8_Segment10" type="revolute">
       <parent link="Segment8"/>
       <child  link="Segment10"/>
       <origin rpy="0 0 0" xyz="0.7388271586659254 -0.7388271586659254 -1.0224077527948014" />
     <axis xyz="0 1 1"/>
       <limit effort="0.0" lower="-3.14159" upper="3.14159" velocity="0.0"/>
    </joint>
    <link name="Segment9">
        <inertial>
            <origin xyz="0.7337668012653984 0.6248896238167058 -0.2827238660283249" rpy="0 0 0"/>
            <mass value="1" />
            <inertia ixx="100" ixy="0" ixz="0" iyy="100" iyz="0" izz="100" />
        </inertial>
        <visual>
            <origin xyz="0.7337668012653984 0.6248896238167058 -0.2827238660283249" rpy="0 0 0"/>
            <geometry>
                <box size="1.4675336025307968 1.2497792476334115 1.1308954641132996" />
            </geometry>
            <material name="Blue">
                <color rgba="0 0 1.0 1.0"/>
            </material>
        </visual>
        <collision>
            <origin xyz="0.7337668012653984 0.6248896238167058 -0.2827238660283249" rpy="0 0 0"/>
            <geometry>
                <box size="1.4675336025307968 1.2497792476334115 1.1308954641132996" />
            </geometry>
        </collision>
    </link>
    <link name="Segment10">
        <inertial>
            <origin xyz="0.7891263031293684 -0.9197555571846858 -0.3667214654628519" rpy="0 0 0"/>
            <mass value="1" />
            <inertia ixx="100" ixy="0" ixz="0" iyy="100" iyz="0" izz="100" />
        </inertial>
        <visual>
            <origin xyz="0.7891263031293684 -0.9197555571846858 -0.3667214654628519" rpy="0 0 0"/>
            <geometry>
                <box size="1.5782526062587368 1.8395111143693716 1.4668858618514076" />
            </geometry>
            <material name="Blue">
                <color rgba="0 0 1.0 1.0"/>
            </material>
        </visual>
        <collision>
            <origin xyz="0.7891263031293684 -0.9197555571846858 -0.3667214654628519" rpy="0 0 0"/>
            <geometry>
                <box size="1.5782526062587368 1.8395111143693716 1.4668858618514076" />
            </geometry>
        </collision>
    </link>
</robot>