<robot name = "robot">
    <link name="Segment0">
        <inertial>
            <origin xyz="0 0 3.1504886514963553" rpy="0 0 0"/>
            <mass value="1" />
            <inertia ixx="100" ixy="0" ixz="0" iyy="100" iyz="0" izz="100" />
        </inertial>
        <visual>
            <origin xyz="0 0 3.1504886514963553" rpy="0 0 0"/>
            <geometry>
                <box size="3 2 1" />
            </geometry>
            <material name="Blue">
                <color rgba="0 0 1.0 1.0"/>
            </material>
        </visual>
        <collision>
            <origin xyz="0 0 3.1504886514963553" rpy="0 0 0"/>
            <geometry>
                <box size="3 2 1" />
            </geometry>
        </collision>
    </link>
    <joint name="Segment0_Segment1" type="revolute">
       <parent link="Segment0"/>
       <child  link="Segment1"/>
       <origin rpy="0 0 0" xyz="-1.5 1.0 2.3808688961200652" />
     <axis xyz="0 1 0"/>
       <limit effort="0.0" lower="-3.14159" upper="3.14159" velocity="0.0"/>
    </joint>
    <joint name="Segment0_Segment2" type="revolute">
       <parent link="Segment0"/>
       <child  link="Segment2"/>
       <origin rpy="0 0 0" xyz="-1.5 -1.0 2.4376162471540903" />
     <axis xyz="0 1 0"/>
       <limit effort="0.0" lower="-3.14159" upper="3.14159" velocity="0.0"/>
    </joint>
    <joint name="Segment0_Segment3" type="revolute">
       <parent link="Segment0"/>
       <child  link="Segment3"/>
       <origin rpy="0 0 0" xyz="1.5 -1.0 2.1203335654082487" />
     <axis xyz="0 1 0"/>
       <limit effort="0.0" lower="-3.14159" upper="3.14159" velocity="0.0"/>
    </joint>
    <joint name="Segment0_Segment4" type="revolute">
       <parent link="Segment0"/>
       <child  link="Segment4"/>
       <origin rpy="0 0 0" xyz="1.5 1.0 2.1647293691607494" />
     <axis xyz="0 1 0"/>
       <limit effort="0.0" lower="-3.14159" upper="3.14159" velocity="0.0"/>
    </joint>
    <link name="Segment1">
        <inertial>
            <origin xyz="0 0 0" rpy="0 0 0"/>
            <mass value="1" />
            <inertia ixx="100" ixy="0" ixz="0" iyy="100" iyz="0" izz="100" />
        </inertial>
        <visual>
            <origin xyz="0 0 0" rpy="0 0 0"/>
            <geometry>
                <box size="0.6423937626772616 0.5765448792156815 0.5392395107525803" />
            </geometry>
            <material name="Blue">
                <color rgba="0 0 1.0 1.0"/>
            </material>
        </visual>
        <collision>
            <origin xyz="0 0 0" rpy="0 0 0"/>
            <geometry>
                <box size="0.6423937626772616 0.5765448792156815 0.5392395107525803" />
            </geometry>
        </collision>
    </link>
    <joint name="Segment1_Segment5" type="revolute">
       <parent link="Segment1"/>
       <child  link="Segment5"/>
       <origin rpy="0 0 0" xyz="0.0 0.0 -0.6785432716335416" />
     <axis xyz="0 1 0"/>
       <limit effort="0.0" lower="-3.14159" upper="3.14159" velocity="0.0"/>
    </joint>
    <link name="Segment2">
        <inertial>
            <origin xyz="0 0 0" rpy="0 0 0"/>
            <mass value="1" />
            <inertia ixx="100" ixy="0" ixz="0" iyy="100" iyz="0" izz="100" />
        </inertial>
        <visual>
            <origin xyz="0 0 0" rpy="0 0 0"/>
            <geometry>
                <box size="0.41224263188999793 0.6110597717304299 0.42574480868452985" />
            </geometry>
            <material name="Green">
                <color rgba="0 1.0 0 1.0"/>
            </material>
        </visual>
        <collision>
            <origin xyz="0 0 0" rpy="0 0 0"/>
            <geometry>
                <box size="0.41224263188999793 0.6110597717304299 0.42574480868452985" />
            </geometry>
        </collision>
    </link>
    <joint name="Segment2_Segment6" type="revolute">
       <parent link="Segment2"/>
       <child  link="Segment6"/>
       <origin rpy="0 0 0" xyz="0.0 -0.0 -0.4452194772978918" />
     <axis xyz="0 1 0"/>
       <limit effort="0.0" lower="-3.14159" upper="3.14159" velocity="0.0"/>
    </joint>
    <link name="Segment3">
        <inertial>
            <origin xyz="0 0 0" rpy="0 0 0"/>
            <mass value="1" />
            <inertia ixx="100" ixy="0" ixz="0" iyy="100" iyz="0" izz="100" />
        </inertial>
        <visual>
            <origin xyz="0 0 0" rpy="0 0 0"/>
            <geometry>
                <box size="0.6290892430638939 0.5948407508794372 1.0603101721762136" />
            </geometry>
            <material name="Green">
                <color rgba="0 1.0 0 1.0"/>
            </material>
        </visual>
        <collision>
            <origin xyz="0 0 0" rpy="0 0 0"/>
            <geometry>
                <box size="0.6290892430638939 0.5948407508794372 1.0603101721762136" />
            </geometry>
        </collision>
    </link>
    <joint name="Segment3_Segment7" type="revolute">
       <parent link="Segment3"/>
       <child  link="Segment7"/>
       <origin rpy="0 0 0" xyz="0.0 0.0 -0.81982721878011" />
     <axis xyz="0 1 0"/>
       <limit effort="0.0" lower="-3.14159" upper="3.14159" velocity="0.0"/>
    </joint>
    <link name="Segment4">
        <inertial>
            <origin xyz="0 0 0" rpy="0 0 0"/>
            <mass value="1" />
            <inertia ixx="100" ixy="0" ixz="0" iyy="100" iyz="0" izz="100" />
        </inertial>
        <visual>
            <origin xyz="0 0 0" rpy="0 0 0"/>
            <geometry>
                <box size="0.5327842304717769 0.7544260274326969 0.9715185646712121" />
            </geometry>
            <material name="Green">
                <color rgba="0 1.0 0 1.0"/>
            </material>
        </visual>
        <collision>
            <origin xyz="0 0 0" rpy="0 0 0"/>
            <geometry>
                <box size="0.5327842304717769 0.7544260274326969 0.9715185646712121" />
            </geometry>
        </collision>
    </link>
    <joint name="Segment4_Segment8" type="revolute">
       <parent link="Segment4"/>
       <child  link="Segment8"/>
       <origin rpy="0 0 0" xyz="0.0 -0.0 -0.744778079688557" />
     <axis xyz="0 1 0"/>
       <limit effort="0.0" lower="-3.14159" upper="3.14159" velocity="0.0"/>
    </joint>
    <link name="Segment5">
        <inertial>
            <origin xyz="0 0 0" rpy="0 0 0"/>
            <mass value="1" />
            <inertia ixx="100" ixy="0" ixz="0" iyy="100" iyz="0" izz="100" />
        </inertial>
        <visual>
            <origin xyz="0 0 0" rpy="0 0 0"/>
            <geometry>
                <box size="0.8501452591319878 0.6246211709076956 0.8178470325145029" />
            </geometry>
            <material name="Blue">
                <color rgba="0 0 1.0 1.0"/>
            </material>
        </visual>
        <collision>
            <origin xyz="0 0 0" rpy="0 0 0"/>
            <geometry>
                <box size="0.8501452591319878 0.6246211709076956 0.8178470325145029" />
            </geometry>
        </collision>
    </link>
    <joint name="Segment5_Segment9" type="revolute">
       <parent link="Segment5"/>
       <child  link="Segment9"/>
       <origin rpy="0 0 0" xyz="0.0 0.0 -0.7691385759571496" />
     <axis xyz="0 1 0"/>
       <limit effort="0.0" lower="-3.14159" upper="3.14159" velocity="0.0"/>
    </joint>
    <link name="Segment6">
        <inertial>
            <origin xyz="0 0 0" rpy="0 0 0"/>
            <mass value="1" />
            <inertia ixx="100" ixy="0" ixz="0" iyy="100" iyz="0" izz="100" />
        </inertial>
        <visual>
            <origin xyz="0 0 0" rpy="0 0 0"/>
            <geometry>
                <box size="0.5676058915059508 0.4430759747774749 0.46469414591125374" />
            </geometry>
            <material name="Blue">
                <color rgba="0 0 1.0 1.0"/>
            </material>
        </visual>
        <collision>
            <origin xyz="0 0 0" rpy="0 0 0"/>
            <geometry>
                <box size="0.5676058915059508 0.4430759747774749 0.46469414591125374" />
            </geometry>
        </collision>
    </link>
    <joint name="Segment6_Segment10" type="revolute">
       <parent link="Segment6"/>
       <child  link="Segment10"/>
       <origin rpy="0 0 0" xyz="0.0 -0.0 -0.6473285920926766" />
     <axis xyz="0 1 0"/>
       <limit effort="0.0" lower="-3.14159" upper="3.14159" velocity="0.0"/>
    </joint>
    <link name="Segment7">
        <inertial>
            <origin xyz="0 0 0" rpy="0 0 0"/>
            <mass value="1" />
            <inertia ixx="100" ixy="0" ixz="0" iyy="100" iyz="0" izz="100" />
        </inertial>
        <visual>
            <origin xyz="0 0 0" rpy="0 0 0"/>
            <geometry>
                <box size="0.71897693912529 0.4298779456935127 0.5793442653840064" />
            </geometry>
            <material name="Blue">
                <color rgba="0 0 1.0 1.0"/>
            </material>
        </visual>
        <collision>
            <origin xyz="0 0 0" rpy="0 0 0"/>
            <geometry>
                <box size="0.71897693912529 0.4298779456935127 0.5793442653840064" />
            </geometry>
        </collision>
    </link>
    <joint name="Segment7_Segment11" type="revolute">
       <parent link="Segment7"/>
       <child  link="Segment11"/>
       <origin rpy="0 0 0" xyz="0.0 0.0 -0.6426131247367247" />
     <axis xyz="0 1 0"/>
       <limit effort="0.0" lower="-3.14159" upper="3.14159" velocity="0.0"/>
    </joint>
    <link name="Segment8">
        <inertial>
            <origin xyz="0 0 0" rpy="0 0 0"/>
            <mass value="1" />
            <inertia ixx="100" ixy="0" ixz="0" iyy="100" iyz="0" izz="100" />
        </inertial>
        <visual>
            <origin xyz="0 0 0" rpy="0 0 0"/>
            <geometry>
                <box size="0.5102011951365903 0.5926946211229178 0.518037594705902" />
            </geometry>
            <material name="Blue">
                <color rgba="0 0 1.0 1.0"/>
            </material>
        </visual>
        <collision>
            <origin xyz="0 0 0" rpy="0 0 0"/>
            <geometry>
                <box size="0.5102011951365903 0.5926946211229178 0.518037594705902" />
            </geometry>
        </collision>
    </link>
    <joint name="Segment8_Segment12" type="revolute">
       <parent link="Segment8"/>
       <child  link="Segment12"/>
       <origin rpy="0 0 0" xyz="0.0 -0.0 -0.6682461563157145" />
     <axis xyz="0 1 0"/>
       <limit effort="0.0" lower="-3.14159" upper="3.14159" velocity="0.0"/>
    </joint>
    <link name="Segment9">
        <inertial>
            <origin xyz="0 0 0" rpy="0 0 0"/>
            <mass value="1" />
            <inertia ixx="100" ixy="0" ixz="0" iyy="100" iyz="0" izz="100" />
        </inertial>
        <visual>
            <origin xyz="0 0 0" rpy="0 0 0"/>
            <geometry>
                <box size="0.6052564702867627 0.5455955503250682 0.7204301193997964" />
            </geometry>
            <material name="Green">
                <color rgba="0 1.0 0 1.0"/>
            </material>
        </visual>
        <collision>
            <origin xyz="0 0 0" rpy="0 0 0"/>
            <geometry>
                <box size="0.6052564702867627 0.5455955503250682 0.7204301193997964" />
            </geometry>
        </collision>
    </link>
    <link name="Segment10">
        <inertial>
            <origin xyz="0 0 0" rpy="0 0 0"/>
            <mass value="1" />
            <inertia ixx="100" ixy="0" ixz="0" iyy="100" iyz="0" izz="100" />
        </inertial>
        <visual>
            <origin xyz="0 0 0" rpy="0 0 0"/>
            <geometry>
                <box size="0.4531989850410449 0.7431036092158504 0.8299630382740993" />
            </geometry>
            <material name="Blue">
                <color rgba="0 0 1.0 1.0"/>
            </material>
        </visual>
        <collision>
            <origin xyz="0 0 0" rpy="0 0 0"/>
            <geometry>
                <box size="0.4531989850410449 0.7431036092158504 0.8299630382740993" />
            </geometry>
        </collision>
    </link>
    <link name="Segment11">
        <inertial>
            <origin xyz="0 0 0" rpy="0 0 0"/>
            <mass value="1" />
            <inertia ixx="100" ixy="0" ixz="0" iyy="100" iyz="0" izz="100" />
        </inertial>
        <visual>
            <origin xyz="0 0 0" rpy="0 0 0"/>
            <geometry>
                <box size="0.794834393947405 0.7826835560129405 0.705881984089443" />
            </geometry>
            <material name="Blue">
                <color rgba="0 0 1.0 1.0"/>
            </material>
        </visual>
        <collision>
            <origin xyz="0 0 0" rpy="0 0 0"/>
            <geometry>
                <box size="0.794834393947405 0.7826835560129405 0.705881984089443" />
            </geometry>
        </collision>
    </link>
    <link name="Segment12">
        <inertial>
            <origin xyz="0 0 0" rpy="0 0 0"/>
            <mass value="1" />
            <inertia ixx="100" ixy="0" ixz="0" iyy="100" iyz="0" izz="100" />
        </inertial>
        <visual>
            <origin xyz="0 0 0" rpy="0 0 0"/>
            <geometry>
                <box size="0.6450708940918557 0.7510067030695762 0.818454717925527" />
            </geometry>
            <material name="Blue">
                <color rgba="0 0 1.0 1.0"/>
            </material>
        </visual>
        <collision>
            <origin xyz="0 0 0" rpy="0 0 0"/>
            <geometry>
                <box size="0.6450708940918557 0.7510067030695762 0.818454717925527" />
            </geometry>
        </collision>
    </link>
</robot>